Workbook
Name _______2005_RETAILS_FOR_MITCH_BY_STATE___VIN: #REF!
Name _02_CAB機能部品: #REF!
Name _02_CAB部品: #REF!
Name _02_CHASSIS部品: #REF!
Name _1_04_kawaguchi: #REF!
Name _1_2005_RETAILS_FOR_MITCH_BY_STATE___VIN: #REF!
Name _10.00_20_14PR: #REF!
Name _10_Q: #REF!
Name _12.6H: #REF!
Name _13.5H: #REF!
Name _14.5H: #REF!
Name _14_4t_Ð_L: #REF!
Name _15.5H: #REF!
Name _15¿: #REF!
Name _16¼_a: #REF!
Name _17ÔÌÞÚ°·: #REF!
Name _18Ã_¼_a: #REF!
Name _19åÌÞÚ°·: #REF!
Name _1MM: #REF!
Name _1st: #REF!
Name _20ñ___\: #REF!
Name _21ø: #REF!
Name _22À²Ô_²½Þ: #REF!
Name _23ÄÙ¸_\: #REF!
Name _25HS10_: #REF!
Name _26_1生_CROSS_クエリー1: #REF!
Name _26HS11_: #REF!
Name _28_出庫リスト_クエリー: #REF!
Name _2nd: #REF!
Name _3: #REF!
Name _30HS15_: 'Monthly 日程1006'!_30HS15_
Name _30HS15_: [0]!_30HS15_
Name _38HS9_: #REF!
Name _39ÌÞÚ_·_í_Þ: #REF!
Name _3rd: #REF!
Name _4_5t.ÃÞ¨½¸: #REF!
Name _4_5t.STD: #REF!
Name _4_5t.ﾃﾞｨｽｸ: #REF!
Name _4th: #REF!
Name _4t巾広: #REF!
Name _5G: #REF!
Name _5th: #REF!
Name _6HE1_TCN: #REF!
Name _6HE1_TCS: #REF!
Name _6HH1_N: #REF!
Name _6HH1_S: #REF!
Name _6th: #REF!
Name _7t: #REF!
Name _7th: #REF!
Name _8.5_Q: #REF!
Name _8_Q: #REF!
Name _EMD２: 'Monthly 日程1006'!_EMD２
Name _EMD２: [0]!_EMD２
Name _HAN02: #REF!
Name _HAN03: #REF!
Name _MC001: #REF!
Name _MC002: #REF!
Name _MC003: #REF!
Name _MC004: #REF!
Name _MC005: #REF!

Sheet 25-45W
A2: ISZ 週別確定内示リスト（25-45W） | H2: FRAME ASSY | AK2: Ｆ生産管理課 川﨑
J3: 45964 | K3: 45971 | L3: 45978 | M3: 45985 | N3: 45992 | O3: 45999 | P3: 46006 | Q3: 46013 | R3: 46020 | S3: 46027 | T3: 46034 | U3: 46041 | V3: 46048 | X3: VK00B1-Gr NUT数：：\\sv1p000001\藤沢工場\工場向け\P24000(生産管理グループ)\藤沢工場共有フォルダ\企画Ｔｷｬﾋﾞﾈｯﾄ\(07)企画共通\01_小型FRAME\00_プロジェクト\VK00\20250217 輸出 NUT増産進捗確認2\コピー250217_対象品番【850幅】S_MBR構成表_20250214_.xlsx | AH3: OBL 構成 | AI3: 720製造管理システム
A4: No. | B4: ライン | C4: 納入品番1 | D4: 車型名称 | E4: 直近イベント | F4: 荷姿 | G4: 刻印 | H4: 初品区分 | I4: 実績有 | J4: 45W | K4: 46W | L4: 47W | M4: 48W | N4: 49W | O4: 50W | P4: 51W | Q4: 52W | R4: 01W | S4: 02W | T4: 03W | U4: 04W | V4: 05W | W4: 総計 | X4: 納入品名称 | Y4: 基本車型 | Z4: 設通NO | AA4: 設通 受領日 | AB4: 受注条件 車型名称 | AC4: イベント車型 | AD4: 送付コメント | AE4: 技計NO | AF4: 生産 ライン | AG4: 刻印 | AI4: 部品ﾋﾟｯｷﾝｸﾞ ﾊﾟﾀｰﾝ検索 | AJ4: C/MBR ﾋﾟｯｷﾝｸﾞ ﾏｽﾀ検索
A5: 31 | B5: D | C5: 7552736070 | D5: VK04 NMR | E5: I3K5323 VK04 DOM向け図面出図 | F5: 1 | H5: 初 | I5: =IF(COUNTIF(ピッキングマスタ作成台帳!C:C,C5)>0,"有","") | N5: 1 | O5: 3 | W5: 4 | X5: FRAME ASM | Y5: VK04 | Z5: I3K5323 | AA5: 45632 | AB5: VK04 NMR | AC5: VK04 A2-Gr 軽量700幅 | AD5: VK04 DOM向け図面出図 VK04 A2-Gr 軽量700幅 | AE5: 0 | AF5: 0 | AG5: 0 | AH5: 未 | AI5: 未 | AJ5: 未 | AR5: #N/A
A6: 30 | B6: D | C6: 7552735880 | D6: VK04 NMR | E6: I3K5323VK04 DOM向け図面出図 | F6: 1 | H6: 初 | I6: =IF(COUNTIF(ピッキングマスタ作成台帳!C:C,C6)>0,"有","") | N6: 1 | W6: 1 | X6: FRAME ASM | Y6: VK04 | Z6: I3K5323 | AA6: 45632 | AB6: VK04 NMR | AC6: VK04 A2-Gr 軽量700幅 | AD6: VK04 DOM向け図面出図 VK04 A2-Gr 軽量700幅 | AE6: 0 | AF6: 0 | AG6: 0 | AH6: 未 | AI6: 未 | AJ6: 未 | AR6: #N/A
A7: 66 | B7: 115 | C7: 7552736100 | D7: VK04 NMR | E7: I3K5323VK04 DOM向け図面出図 | F7: 1 | G7: FBH | H7: 初 | I7: =IF(COUNTIF(ピッキングマスタ作成台帳!C:C,C7)>0,"有","") -> 有 | K7: 1 | W7: 1 | X7: FRAME ASM | Y7: VK04 | Z7: I3K5323 | AA7: 45632 | AB7: VK04 NMR | AC7: VK04 A2-Gr 軽量700幅 | AD7: VK04 DOM向け図面出図 VK04 A2-Gr 軽量700幅 | AE7: 0 | AF7: 0 | AG7: 0 | AH7: 未 | AI7: 未 | AJ7: 未 | AR7: #N/A
A8: 67 | B8: 115 | C8: 7552736110 | D8: VK04 NMR | E8: I3K5323VK04 DOM向け図面出図 | F8: 1 | G8: FBG | H8: 初 | I8: =IF(COUNTIF(ピッキングマスタ作成台帳!C:C,C8)>0,"有","") -> 有 | K8: 1 | W8: 1 | X8: FRAME ASM | Y8: VK04 | Z8: I3K5323 | AA8: 45632 | AB8: VK04 NMR | AC8: VK04 A2-Gr 軽量700幅 | AD8: VK04 DOM向け図面出図 VK04 A2-Gr 軽量700幅 | AE8: 0 | AF8: 0 | AG8: 0 | AH8: 未 | AI8: 未 | AJ8: 未 | AR8: #N/A
A9: 53 | B9: 115 | C9: 7552715130 | D9: NMR | E9: I3K5492VK05 A-GR 欧州/トルコ/UK向け 新規出図 | F9: 1 | G9: FBN | H9: 初 | I9: =IF(COUNTIF(ピッキングマスタ作成台帳!C:C,C9)>0,"有","") -> 有 | K9: 1 | W9: 1 | X9: FRAME ASM | Y9: NMR | Z9: I3K5492 | AA9: 45726 | AB9: VK05 A-Gr | AC9: VK05A-Gr | AD9: VK05 A-Gr 欧州/トルコ/UK向け 新規出図 | AE9: 0 | AF9: 0 | AG9: 0 | AH9: 未 | AI9: 未 | AJ9: 未 | AR9: 7552715130
A10: 49 | B10: 115 | C10: 7552702910 | D10: VK05 | E10: I4K5796VK04 A2-GR 1生向け設変出図 | F10: 1 | G10: DBT | H10: 初 | I10: =IF(COUNTIF(ピッキングマスタ作成台帳!C:C,C10)>0,"有","") -> 有 | K10: 1 | W10: 1 | X10: FRAME ASM | Y10: VK05 | Z10: I3K5442 | AA10: 45677 | AB10: VK05 NMR | AC10: VK05 A-Gr | AD10: VK05 A/B Gr K研向け出図 | AE10: PA1-5042 | AF10: Ｄ | AG10: DBT | AH10: 未 | AI10: 未 | AJ10: 未 | AR10: 7552702910
A11: 56 | B11: 115 | C11: 7552735780 | D11: VK04 NKR | E11: VK04 A2-GR 1生向け設変出図 | F11: 1 | G11: DBX | H11: 初 | I11: =IF(COUNTIF(ピッキングマスタ作成台帳!C:C,C11)>0,"有","") -> 有 | K11: 7 | L11: 1 | M11: 2 | N11: 10 | O11: 10 | P11: 8 | Q11: 8 | S11: 10 | T11: 9 | U11: 9 | V11: 5 | W11: 79 | X11: FRAME ASM | Y11: VK04 | Z11: I3K5323 | AA11: 45632 | AB11: VK04 NKR | AC11: VK04 A2-Gr 軽量700幅 | AD11: VK04 DOM向け図面出図 VK04 A2-Gr 軽量700幅 | AE11: PA1-5070 | AF11: D | AG11: DBX | AH11: 未 | AI11: 未 | AJ11: 未 | AR11: #N/A
A12: 54 | B12: 115 | C12: 7552735180 | D12: VK04 NKR | E12: VK04 DOM向け図面出図 | F12: 1 | G12: DCE | H12: 初 | I12: =IF(COUNTIF(ピッキングマスタ作成台帳!C:C,C12)>0,"有","") -> 有 | K12: 1 | L12: 1 | M12: 1 | N12: 3 | P12: 1 | T12: 1 | W12: 8 | X12: FRAME ASM | Y12: VK04 | Z12: I3K5323 | AA12: 45632 | AB12: VK04 NKR | AC12: VK04 A2-Gr 軽量700幅 | AD12: VK04 DOM向け図面出図 VK04 A2-Gr 軽量700幅 | AE12: 0 | AF12: 0 | AG12: 0 | AH12: 未 | AI12: 未 | AJ12: 未 | AR12: #N/A
A13: 57 | B13: 115 | C13: 7552735790 | D13: VK04 NKR | E13: VK04 DOM向け図面出図 | F13: 1 | G13: DBY | H13: 初 | I13: =IF(COUNTIF(ピッキングマスタ作成台帳!C:C,C13)>0,"有","") -> 有 | K13: 14 | L13: 4 | M13: 4 | N13: 11 | O13: 43 | P13: 41 | Q13: 31 | S13: 24 | T13: 17 | U13: 13 | V13: 8 | W13: 210 | X13: FRAME ASM | Y13: VK04 | Z13: I3K5323 | AA13: 45632 | AB13: VK04 NKR | AC13: VK04 A2-Gr 軽量700幅 | AD13: VK04 DOM向け図面出図 VK04 A2-Gr 軽量700幅 | AE13: PA1-5070 | AF13: D | AG13: DBY | AH13: 未 | AI13: 未 | AJ13: 未 | AR13: #N/A
A14: 58 | B14: 115 | C14: 7552735800 | D14: VK04 NKR | E14: VK04 DOM向け図面出図 | F14: 1 | G14: DCG | H14: 初 | I14: =IF(COUNTIF(ピッキングマスタ作成台帳!C:C,C14)>0,"有","") -> 有 | K14: 1 | L14: 1 | M14: 1 | N14: 1 | O14: 1 | T14: 1 | U14: 1 | W14: 7 | X14: FRAME ASM | Y14: VK04 | Z14: I3K5323 | AA14: 45632 | AB14: VK04 NKR | AC14: VK04 A2-Gr 軽量700幅 | AD14: VK04 DOM向け図面出図 VK04 A2-Gr 軽量700幅 | AE14: 0 | AF14: 0 | AG14: 0 | AH14: 未 | AI14: 未 | AJ14: 未 | AR14: #N/A
A15: 60 | B15: 115 | C15: 7552735840 | D15: VK04 NKR | E15: VK04 DOM向け図面出図 | F15: 1 | G15: DCD | H15: 初 | I15: =IF(COUNTIF(ピッキングマスタ作成台帳!C:C,C15)>0,"有","") -> 有 | K15: 1 | L15: 2 | M15: 7 | N15: 1 | O15: 3 | P15: 3 | Q15: 4 | S15: 5 | T15: 5 | U15: 5 | V15: 3 | W15: 39 | X15: FRAME ASM | Y15: VK04 | Z15: I3K5323 | AA15: 45632 | AB15: VK04 NKR | AC15: VK04 A2-Gr 軽量700幅 | AD15: VK04 DOM向け図面出図 VK04 A2-Gr 軽量700幅 | AE15: 0 | AF15: 0 | AG15: 0 | AH15: 未 | AI15: 未 | AJ15: 未 | AR15: #N/A
A16: 61 | B16: 115 | C16: 7552735850 | D16: VK04 NKR | E16: VK04 DOM向け図面出図 | F16: 1 | G16: DCF | H16: 初 | I16: =IF(COUNTIF(ピッキングマスタ作成台帳!C:C,C16)>0,"有","") -> 有 | K16: 1 | L16: 2 | M16: 1 | W16: 4 | X16: FRAME ASM | Y16: VK04 | Z16: I3K5323 | AA16: 45632 | AB16: VK04 NKR | AC16: VK04 A2-Gr 軽量700幅 | AD16: VK04 DOM向け図面出図 VK04 A2-Gr 軽量700幅 | AE16: 0 | AF16: 0 | AG16: 0 | AH16: 未 | AI16: 未 | AJ16: 未 | AR16: #N/A
A17: 62 | B17: 115 | C17: 7552735870 | D17: VK04 NMR | E17: VK04 DOM向け図面出図 | F17: 1 | H17: 初 | I17: =IF(COUNTIF(ピッキングマスタ作成台帳!C:C,C17)>0,"有","") -> 有 | K17: 1 | M17: 1 | N17: 7 | O17: 18 | P17: 22 | Q17: 18 | S17: 18 | T17: 15 | U17: 11 | V17: 7 | W17: 118 | X17: FRAME ASM | Y17: VK04 | Z17: I3K5323 | AA17: 45632 | AB17: VK04 NMR | AC17: VK04 A2-Gr 軽量700幅 | AD17: VK04 DOM向け図面出図 VK04 A2-Gr 軽量700幅 | AE17: 0 | AF17: 0 | AG17: 0 | AH17: 未 | AI17: 未 | AJ17: 未 | AR17: #N/A
A18: 64 | B18: 115 | C18: 7552735980 | D18: VK04 NKR | E18: VK04 DOM向け図面出図 | F18: 1 | G18: FBF | H18: 初 | I18: =IF(COUNTIF(ピッキングマスタ作成台帳!C:C,C18)>0,"有","") -> 有 | K18: 1 | W18: 1 | X18: FRAME ASM | Y18: VK04 | Z18: I3K5323 | AA18: 45632 | AB18: VK04 NKR | AC18: VK04 A2-Gr 軽量700幅 | AD18: VK04 DOM向け図面出図 VK04 A2-Gr 軽量700幅 | AE18: 0 | AF18: 0 | AG18: 0 | AH18: 未 | AI18: 未 | AJ18: 未 | AR18: #N/A
A19: 59 | B19: 115 | C19: 7552735810 | D19: VK04 NKR | E19: I3K5323VK04 DOM向け図面出図 | F19: 1 | H19: 初 | I19: =IF(COUNTIF(ピッキングマスタ作成台帳!C:C,C19)>0,"有","") -> 有 | L19: 1 | W19: 1 | X19: FRAME ASM | Y19: VK04 | Z19: I3K5323 | AA19: 45632 | AB19: VK04 NKR | AC19: VK04 A2-Gr 軽量700幅 | AD19: VK04 DOM向け図面出図 VK04 A2-Gr 軽量700幅 | AE19: 0 | AF19: 0 | AG19: 0 | AH19: 未 | AI19: 未 | AJ19: 未 | AR19: #N/A
A20: 55 | B20: 115 | C20: 7552735190 | D20: VK04 NKR | E20: VK04 DOM向け図面出図 | F20: 1 | H20: 初 | I20: =IF(COUNTIF(ピッキングマスタ作成台帳!C:C,C20)>0,"有","") -> 有 | M20: 1 | N20: 2 | O20: 1 | P20: 1 | Q20: 1 | T20: 1 | W20: 7 | X20: FRAME ASM | Y20: VK04 | Z20: I3K5323 | AA20: 45632 | AB20: VK04 NKR | AC20: VK04 A2-Gr 軽量700幅 | AD20: VK04 DOM向け図面出図 VK04 A2-Gr 軽量700幅 | AE20: 0 | AF20: 0 | AG20: 0 | AH20: 未 | AI20: 未 | AJ20: 未 | AR20: #N/A
A21: 63 | B21: 115 | C21: 7552735890 | D21: VK04 NMR | E21: I3K5323VK04 DOM向け図面出図 | F21: 1 | H21: 初 | I21: =IF(COUNTIF(ピッキングマスタ作成台帳!C:C,C21)>0,"有","") -> 有 | N21: 2 | O21: 4 | P21: 4 | Q21: 3 | S21: 3 | T21: 2 | U21: 2 | V21: 1 | W21: 21 | X21: FRAME ASM | Y21: VK04 | Z21: I3K5323 | AA21: 45632 | AB21: VK04 NMR | AC21: VK04 A2-Gr 軽量700幅 | AD21: VK04 DOM向け図面出図 VK04 A2-Gr 軽量700幅 | AE21: 0 | AF21: 0 | AG21: 0 | AH21: 未 | AI21: 未 | AJ21: 未 | AR21: #N/A
A22: 65 | B22: 115 | C22: 7552736030 | D22: VK04 NMR | E22: VK04 DOM向け図面出図 | F22: 1 | G22: FBJ | H22: 初 | I22: =IF(COUNTIF(ピッキングマスタ作成台帳!C:C,C22)>0,"有","") -> 有 | N22: 1 | O22: 4 | P22: 4 | Q22: 3 | S22: 4 | T22: 4 | U22: 2 | V22: 1 | W22: 23 | X22: FRAME ASM | Y22: VK04 | Z22: I3K5323 | AA22: 45632 | AB22: VK04 NMR | AC22: VK04 A2-Gr 軽量700幅 | AD22: VK04 DOM向け図面出図 VK04 A2-Gr 軽量700幅 | AE22: 0 | AF22: 0 | AG22: 0 | AH22: 未 | AI22: 未 | AJ22: 未 | AR22: #N/A
A23: 390 | B23: A | C23: 7552282532 | D23: VK00 N** | E23: I4K5443VK00 3X 850幅 B1-GR FRAME ASM 設変出図(内容：FRAME ASM内容品最新化,S/M ASM LH 溶接NUT及びSTIFF SUB SPG BRKT追加,RIVET削除,REINF LH 溶接NUT追加) | F23: 1 | H23: 初 | I23: =IF(COUNTIF(ピッキングマスタ作成台帳!C:C,C23)>0,"有","") | S23: 3 | W23: 3 | X23: FRAME ASM | Y23: VK00 | Z23: I4K5443 | AA23: 45527 | AB23: VK00 N** | AC23: VK00 B1-Gr 850幅 | AD23: VK00 3X 850幅 B1-GR FRAME ASM 設変出図(内容：FRAME ASM内容品最新化,S/M ASM LH 溶接NUT及びSTIFF SUB SPG BRKT追加,RIVET削除,REINF LH 溶接NUT追加) | AE23: 0 | AF23: 0 | AG23: 0 | AH23: 未 | AI23: 未 | AJ23: 未 | AR23: #N/A
A24: 648 | B24: A | C24: 7552703000 | D24: NMR | E24: VK05 A-GR 欧州/トルコ/UK向け 新規出図 | F24: 3 | H24: 初 | I24: =IF(COUNTIF(ピッキングマスタ作成台帳!C:C,C24)>0,"有","") -> 有 | J24: 6 | K24: 12 | L24: 12 | M24: 12 | O24: 24 | W24: 66 | X24: FRAME ASM | Y24: NMR | Z24: I3K5492 | AA24: 45726 | AB24: VK05 A-Gr | AC24: VK05A-Gr | AD24: VK05 A-Gr 欧州/トルコ/UK向け 新規出図 | AE24: 0 | AF24: D | AG24: 0 | AH24: 未 | AI24: 未 | AJ24: 未 | AR24: #N/A
A25: 428 | B25: A | C25: 7552714200 | D25: VL26 N*R | E25: VL26 A2-GR 一生 国内特装車FRAME ASM、SIDE MEMBER新規出図 | F25: 1 | H25: 初 | I25: =IF(COUNTIF(ピッキングマスタ作成台帳!C:C,C25)>0,"有","") -> 有 | J25: 1 | W25: 1 | X25: FRAME ASM | Y25: VL26 | Z25: I3K5179 | AA25: 45575 | AB25: VL26 N*R | AC25: VL26 A2-GR | AD25: VL26 A2-GR 一生 国内特装車FRAME ASM、SIDE MEMBER新規出図 | AE25: 未 | AF25: 0 | AG25: 0 | AH25: 未 | AI25: 未 | AJ25: 未 | AR25: #N/A
A26: 167 | B26: A | C26: 7551885272 | D26: VK00 NPR | E26: I4JKV99VK00 3X 750幅 FRAME ASM 設変出図(サ変、NUT,RIVETの変更) ※AAS-LD-12565 | F26: 1 | H26: 初 | I26: =IF(COUNTIF(ピッキングマスタ作成台帳!C:C,C26)>0,"有","") -> 有 | K26: 1 | W26: 1 | X26: FRAME ASM | Y26: VK00 | Z26: I4JKV99 | AA26: 45202 | AB26: VK00 NPR | AC26: 3X 750幅 | AD26: 【I4JKV99】VK00 3X 750幅 FRAME ASM 設変出図(サ変、NUT,RIVETの変更) ※AAS-LD-12565 | AE26: PA1-3218 | AF26: A | AG26: SCE | AH26: 未 | AI26: 未 | AJ26: 未 | AR26: #N/A
A27: 203 | B27: A | C27: 7551885911 | D27: VK04 NPS | E27: I4K6268VK04 A1-GR 4*4 量産向け設変出図 | F27: 1 | H27: 初 | I27: =IF(COUNTIF(ピッキングマスタ作成台帳!C:C,C27)>0,"有","") -> 有 | K27: 1 | L27: 5 | W27: 6 | X27: FRAME ASM | Y27: VK04 | Z27: I4K6268 | AA27: 45677 | AB27: VK04 NPS | AC27: VK04 A1-Gr | AD27: VK04 A1-Gr 4X4 量産向け設変出図 | AE27: 0 | AF27: 0 | AG27: 0 | AH27: 未 | AI27: 未 | AJ27: 未 | AR27: #N/A
A28: 443 | B28: A | C28: 8972681162 | D28: VK04 NPS | E28: I4K6268VK04 A1-GR 4*4 量産向け設変出図 | F28: 1 | H28: 初 | I28: =IF(COUNTIF(ピッキングマスタ作成台帳!C:C,C28)>0,"有","") -> 有 | K28: 1 | Q28: 1 | S28: 1 | T28: 1 | W28: 4 | X28: FRAME ASM | Y28: VK04 | Z28: I4K6268 | AA28: 45677 | AB28: VK04 NPS | AC28: VK04 A1-Gr | AD28: VK04 A1-Gr 4X4 量産向け設変出図 | AE28: 0 | AF28: 0 | AG28: 0 | AH28: 未 | AI28: 未 | AJ28: 未 | AR28: #N/A
A29: 204 | B29: A | C29: 7551885921 | D29: VK04 NPS | E29: VK04 A1/A2-GR 1生向け設変出図 | F29: 1 | H29: 初 | I29: =IF(COUNTIF(ピッキングマスタ作成台帳!C:C,C29)>0,"有","") -> 有 | K29: 1 | L29: 3 | W29: 4 | X29: FRAME ASM | Y29: VK04 | Z29: I4K6268 | AA29: 45677 | AB29: VK04 NPS | AC29: VK04 A1-Gr | AD29: VK04 A1-Gr 4X4 量産向け設変出図 | AE29: 0 | AF29: 0 | AG29: 0 | AH29: 未 | AI29: 未 | AJ29: 未 | AR29: #N/A
A30: 599 | B30: A | C30: 8978794961 | D30: VK04 NPS | E30: VK04 A1-GR 4*4 量産向け設変出図 | F30: 1 | H30: 初 | I30: =IF(COUNTIF(ピッキングマスタ作成台帳!C:C,C30)>0,"有","") -> 有 | K30: 1 | L30: 4 | W30: 5 | X30: FRAME ASM | Y30: VK04 | Z30: I4K6268 | AA30: 45677 | AB30: VK04 NPS | AC30: VK04 A1-Gr | AD30: VK04 A1-Gr 4X4 量産向け設変出図 | AE30: 0 | AF30: 0 | AG30: 0 | AH30: 未 | AI30: 未 | AJ30: 未 | AR30: #N/A
A31: 600 | B31: A | C31: 8978794971 | D31: VK04 NPS | E31: VK04 A1-GR 4*4 量産向け設変出図 | F31: 1 | H31: 初 | I31: =IF(COUNTIF(ピッキングマスタ作成台帳!C:C,C31)>0,"有","") -> 有 | K31: 1 | W31: 1 | X31: FRAME ASM | Y31: VK04 | Z31: I4K6268 | AA31: 45677 | AB31: VK04 NPS | AC31: VK04 A1-Gr | AD31: VK04 A1-Gr 4X4 量産向け設変出図 | AE31: 0 | AF31: A | AG31: 0 | AH31: 未 | AI31: 未 | AJ31: 未 | AR31: #N/A
A32: 601 | B32: A | C32: 8978794982 | D32: VK04 NPS | E32: VK04 A1-GR 4*4 量産向け設変出図 | F32: 1 | H32: 初 | I32: =IF(COUNTIF(ピッキングマスタ作成台帳!C:C,C32)>0,"有","") -> 有 | K32: 1 | L32: 1 | M32: 1 | N32: 2 | W32: 5 | X32: FRAME ASM | Y32: VK04 | Z32: I4K6268 | AA32: 45677 | AB32: VK04 NPS | AC32: VK04 A1-Gr | AD32: VK04 A1-Gr 4X4 量産向け設変出図 | AE32: 0 | AF32: 0 | AG32: 0 | AH32: 未 | AI32: 未 | AJ32: 未 | AR32: #N/A
A33: 270 | B33: A | C33: 7551910170 | D33: VK00 NKR | E33: I3JBZ26VK00 1X RIGID 一生向けFRAME ASM 新規出図 | F33: 1 | H33: 初 | I33: =IF(COUNTIF(ピッキングマスタ作成台帳!C:C,C33)>0,"有","") -> 有 | L33: 1 | M33: 1 | W33: 2 | X33: FRAME ASM | Y33: VK00 | Z33: I3JBZ26 | AA33: 44963 | AB33: VK00 NKR | AC33: VK00 1X 標準 | AD33: 【I3JBZ26】VK00 1X RIGID 一生向けFRAME ASM 新規出図 | AE33: PA1-3108 | AF33: A | AG33: CBR | AH33: 未 | AI33: 未 | AJ33: 未 | AR33: #N/A
A34: 432 | B34: A | C34: 7552736020 | D34: VK04 NMR | E34: I3K5323VK04 DOM向け図面出図 | F34: 1 | H34: 初 | I34: =IF(COUNTIF(ピッキングマスタ作成台帳!C:C,C34)>0,"有","") -> 有 | L34: 5 | M34: 19 | Q34: 4 | S34: 11 | T34: 12 | U34: 11 | V34: 8 | W34: 70 | X34: FRAME ASM | Y34: VK04 | Z34: I3K5323 | AA34: 45632 | AB34: VK04 NMR | AC34: VK04 A2-Gr 軽量700幅 | AD34: VK04 DOM向け図面出図 VK04 A2-Gr 軽量700幅 | AE34: 0 | AF34: D | AG34: 0 | AH34: 未 | AI34: 未 | AJ34: 未 | AR34: #N/A
A35: 404 | B35: A | C35: 7552626170 | D35: VK04 NPS | E35: I3K5404VK04 A1/A2-GR 1生向け FRAME新規出図 | F35: 1 | H35: 初 | I35: =IF(COUNTIF(ピッキングマスタ作成台帳!C:C,C35)>0,"有","") -> 有 | L35: 1 | M35: 1 | W35: 2 | X35: FRAME ASM | Y35: VK04 | Z35: I3K5404 | AA35: 45693 | AB35: VK04 NPS | AC35: VK04 A1/A2-Gr | AD35: VK04 A1/A2-Gr 1SEI向け新規出図 | AE35: 0 | AF35: 0 | AG35: 0 | AH35: 未 | AI35: 未 | AJ35: 未 | AR35: #N/A
A36: 647 | B36: A | C36: 7552702970 | D36: VK00/VK05 | E36: I3K5492VK05 A-GR 欧州/トルコ/UK向け 新規出図 | F36: 3 | H36: 初 | I36: =IF(COUNTIF(ピッキングマスタ作成台帳!C:C,C36)>0,"有","") -> 有 | L36: 6 | N36: 30 | O36: 12 | W36: 48 | X36: FRAME ASM | Y36: NMR | Z36: I3K5492 | AA36: 45726 | AB36: VK05 A-Gr | AC36: VK05A-Gr | AD36: VK05 A-Gr 欧州/トルコ/UK向け 新規出図 | AE36: 0 | AF36: Ｄ | AG36: 0 | AH36: 未 | AI36: 未 | AJ36: 未 | AR36: #N/A
A37: 431 | B37: A | C37: 7552735860 | D37: VK04 NMR | E37: I3K5323VK04 DOM向け図面出図 | F37: 1 | H37: 初 | I37: =IF(COUNTIF(ピッキングマスタ作成台帳!C:C,C37)>0,"有","") -> 有 | M37: 2 | N37: 8 | O37: 13 | P37: 11 | Q37: 15 | S37: 28 | T37: 25 | U37: 24 | V37: 16 | W37: 142 | X37: FRAME ASM | Y37: VK04 | Z37: I3K5323 | AA37: 45632 | AB37: VK04 NMR | AC37: VK04 A2-Gr 軽量700幅 | AD37: VK04 DOM向け図面出図 VK04 A2-Gr 軽量700幅 | AE37: 0 | AF37: D | AG37: 0 | AH37: 未 | AI37: 未 | AJ37: 未 | AR37: #N/A
A38: 603 | B38: A | C38: 8978795024 | D38: VK04 NPS | E38: I4K6626 VK04 A1/A2-GR 1生向け設変出図 | F38: 1 | H38: 初 | I38: =IF(COUNTIF(ピッキングマスタ作成台帳!C:C,C38)>0,"有","") -> 有 | M38: 1 | W38: 1 | X38: FRAME ASM | Y38: VK04 | Z38: I4K6268 | AA38: 45677 | AB38: VK04 NPS | AC38: VK04 A1-Gr | AD38: VK04 A1-Gr 4X4 量産向け設変出図 | AE38: 0 | AF38: A | AG38: 0 | AH38: 未 | AI38: 未 | AJ38: 未 | AR38: #N/A
A39: 392 | B39: A | C39: 7552312870 | D39: VK02 NMR | E39: I3K4019VK02 A-GR K研 FRAME ASM 新規出図 | F39: 1 | G39: JL7 | H39: 初 | I39: =IF(COUNTIF(ピッキングマスタ作成台帳!C:C,C39)>0,"有","") -> 有 | P39: 1 | W39: 1 | X39: FRAME ASM | Y39: VK02 | Z39: I3K4019 | AA39: 0 | AB39: VK02NMR | AC39: VK02 A-Gr | AD39: 0 | AE39: PA1-5089 | AF39: A | AG39: JL7 | AH39: 未 | AI39: 未 | AJ39: 未
A40: 168 | B40: A | C40: 7551885322 | D40: VK00 NPR | E40: I4JKV99VK00 3X 750幅 FRAME ASM 設変出図(サ変、NUT,RIVETの変更) ※AAS-LD-12565 | F40: 1 | H40: 初 | I40: =IF(COUNTIF(ピッキングマスタ作成台帳!C:C,C40)>0,"有","") -> 有 | Q40: 1 | W40: 1 | X40: FRAME ASM | Y40: VK00 | Z40: I4JKV99 | AA40: 45202 | AB40: VK00 NPR | AC40: 3X 750幅 | AD40: 【I4JKV99】VK00 3X 750幅 FRAME ASM 設変出図(サ変、NUT,RIVETの変更) ※AAS-LD-12565 | AE40: PA1-3218 | AF40: A | AG40: SCK | AH40: 未 | AI40: 未 | AJ40: 未 | AR40: #N/A
A41: 352 | B41: A | C41: 7552222921 | D41: VK00 NKR | E41: VK00 B2-GR 一生向け 700幅 設変出図(内容:構成部品の最新化、溶接NUT変更) | F41: 1 | H41: 初 | I41: =IF(COUNTIF(ピッキングマスタ作成台帳!C:C,C41)>0,"有","") -> 有 | Q41: 1 | S41: 1 | T41: 1 | U41: 1 | W41: 4 | X41: FRAME ASM | Y41: VK00 | Z41: I4K5030 | AA41: 45450 | AB41: VK00 NKR | AC41: VK00 B2-Gr 700幅 | AD41: VK00 B2-GR 一生向け 700幅 設変出図(内容:構成部品の最新化、溶接NUT変更) | AE41: 0 | AF41: A | AG41: 0 | AH41: 未 | AI41: 未 | AJ41: 未
...

Sheet ピッキングマスタ作成台帳
A1: 番号 | B1: ライン | C1: 新規作成品番 | D1: 車型 | E1: 指示月日 | F1: OBL有り | G1: BCD部品 | H1: C | I1: 作成日 | J1: 管理台帳インプット | K1: 備考(流用元,他)
A2: 1 | B2: ライン未定 | C2: 7551885291 | D2: 7551885182 | E2: 45141 | I2: 45141 | J2: 済み
A3: 2 | B3: Aライン、部品クロス要 | C3: 8978794953 | D3: 7551885771 | E3: 45222 | I3: 45217 | J3: 45217
A4: 3 | B4: Aライン、部品クロス要 | C4: 7551885261 | D4: 7551885251 | E4: 45223 | I4: 45217 | J4: 45217
A5: 4 | B5: Ｃライン、クロス要 | C5: 7552132070 | E5: 45224 | I5: 45219 | J5: 45219
A6: 5 | B6: Ｃライン、クロス要 | C6: 7552166200 | E6: 45226 | I6: 45219 | J6: 45219
A7: 6 | B7: Aライン、部品クロス要 | C7: 7551885901 | D7: 8978794953 | E7: 45229 | I7: 45217 | J7: 45217
A8: 7 | B8: Aライン、部品クロス要 | C8: 7551946351 | D8: 7551945900 | E8: 45229 | I8: 45218 | J8: 45218
A9: 8 | B9: Aライン、部品クロス要 | C9: 7552078500 | D9: 8972782950 | E9: 45229 | I9: 45218 | J9: 45218
A10: 9 | B10: Aライン、部品クロス要 | C10: 7552078580 | D10: 8984896672 | E10: 45229 | I10: 45218 | J10: 45218
A11: 10 | B11: Aライン、部品クロス要 | C11: 7551946261 | D11: 7551946370 | E11: 45229 | I11: 45219 | J11: 45219
A12: 11 | B12: Ｃライン、クロス要 | C12: 7552138860 | E12: 45229 | I12: 45219 | J12: 45219
A13: 12 | B13: Aライン、部品クロス要 | C13: 8977943333 | D13: 7551909210 | E13: 45229 | I13: 45219 | J13: 45219
A14: 13 | B14: Aライン、部品クロス要 | C14: 8978363712 | D14: 8978767222 | E14: 45229 | I14: 45223 | J14: 45223
A15: 14 | B15: Aライン、部品クロス要 | C15: 8978794853 | D15: 8978794852 | E15: 45229 | I15: 45224 | J15: 45224
A16: 15 | B16: Aライン、部品クロス要 | C16: 7551885761 | D16: 8978794422 | E16: 45236 | I16: 45224 | J16: 45224
A17: 16 | B17: Aライン、部品クロス要 | C17: 8972681151 | D17: 7551885512 | E17: 45236 | I17: 45224 | J17: 45224
A18: 17 | B18: Aライン、部品クロス要 | C18: 8978767382 | D18: 8978767381 | E18: 45236 | I18: 45225 | J18: 45225
A19: 18 | B19: Ｃライン、クロス要 | C19: 8978836720 | D19: 897676278 | E19: 45237 | I19: 45222
A20: 19 | B20: Aライン、部品クロス要 | C20: 7551885202 | D20: 7551885351 | E20: 45243 | I20: 45225 | J20: 45225
A21: 20 | B21: Aライン、部品クロス要 | C21: 7552078260 | D21: 8983882992 | E21: 45243 | I21: 45226 | J21: 45226
A22: 21 | B22: Aライン、部品クロス要 | C22: 7552078300 | D22: 8975435240 | E22: 45243 | I22: 45226 | J22: 45226
A23: 22 | B23: Aライン、部品クロス要 | C23: 7552078340 | D23: 7552078320 | E23: 45243 | I23: 45226 | J23: 45226
A24: 23 | B24: Aライン、部品クロス要 | C24: 7552078830 | D24: 7552078880 | E24: 45243 | I24: 45229 | J24: 45229
A25: 24 | B25: Aライン、部品クロス要 | C25: 7552078890 | D25: 8972752250 | E25: 45243 | I25: 45232 | J25: 45232
A26: 25 | B26: Ｃライン、クロス要 | C26: 8972416553 | D26: 7552138860 | E26: 45243 | I26: 45232 | J26: 45232
A27: 26 | B27: Ｃライン、クロス要 | C27: 7551960840 | D27: 7551960640 | E27: 45243 | I27: 45233 | J27: 45236
A28: 27 | B28: Ｃライン、クロス要 | C28: 8972416584 | D28: 7552132050 | E28: 45243 | I28: 45233 | J28: 45236
A29: 28 | B29: Aライン、部品クロス要 | C29: 8977943713 | D29: 7551909300 | E29: 45243 | I29: 45233 | J29: 45236
A30: 29 | B30: Aライン、部品クロス要 | C30: 8978794712 | D30: 7551885801 | E30: 45243 | I30: 45233 | J30: 45236
A31: 30 | B31: Aライン、部品クロス要 | C31: 8978794892 | D31: 7551885182 | E31: 45243 | I31: 45233 | J31: 45236
... A44: 43 | B44: Aライン、部品クロス要 | C44: 7552078240 | D44: 8976538960 | E44: 45271 | I44: 45260 | J44: 45260
A45: 44 | B45: Aライン、部品クロス要 | C45: 7552078250 | D45: 8983883001 | E45: 45271 | I45: 45260 | J45: 45260 | L45: =D45 -> 8983883001
A46: 45 | B46: Aライン、部品クロス要 | C46: 7552078270 | D46: 8976539000 | E46: 45271 | I46: 45260 | J46: 45260
A47: 46 | B47: Aライン、部品クロス要 | C47: 7552078310 | D47: 7552078270 | E47: 45271 | I47: 45260 | J47: 45260
A48: 47 | B48: Aライン、部品クロス要 | C48: 7552078350 | D48: 8975435250 | E48: 45271 | I48: 45260 | J48: 45260
A49: 48 | B49: Aライン、部品クロス要 | C49: 7552078390 | D49: 8984896132 | E49: 45271 | I49: 45260 | J49: 45260
A50: 49 | B50: Aライン、部品クロス要 | C50: 7552078400 | D50: 8984896112 | E50: 45271 | I50: 45260 | J50: 45260
A51: 50 | B51: Aライン、部品クロス要 | C51: 7552078530 | D51: 8984896661 | E51: 45271 | I51: 45260 | J51: 45260
A52: 51 | B52: Aライン、部品クロス要 | C52: 7552078860 | D52: 7552078880 | E52: 45271 | I52: 45260 | J52: 45260
...

Sheet 設変
W1: 藤沢工場 生産管理課
B2: 小型FRAME Weekly MTG | W2: 承認 | X2: 審査 | Y2: 作成 | AB2: ○ | AC2: ：参加
W3: 井上 | Y3: 寺田 | AB3: ― | AC3: ：不参加
C5: 【出席者】
D6: 技術課 | K6: 品管課 | M6: 組一課 | P6: 自動車営業部 | S6: 設計部 | V6: 調達 | W6: プレス | X6: 生管課
D7: 松本課長 | E7: 笹主任 | F7: 櫻井担当 | G7: 長田担当 | H7: 高橋担当 | I7: イー担当 | J7: 宮澤担当 | K7: 大木担当 | L7: 川口担当 | M7: 川上課長 | N7: 綿引担当 | O7: 菱沼担当 | P7: 吉永課長 | Q7: 斉木主任 | R7: 岡担当 | S7: 郡上主任 | T7: 瀧澤担当 | U7: 根津担当 | V7: 木村担当 | W7: 福島主任 | X7: 長友主任 | Y7: 中村担当 | Z7: 三浦担当 | AA7: 伊藤担当 | AB7: 寺田
C8: 設変 | D8: ― | E8: ○ | F8: ○ | G8: ― | H8: ○ | I8: ○ | J8: ○ | K8: ○ | L8: ― | M8: ― | N8: ― | O8: ― | P8: ― | Q8: ― | R8: ○ | S8: ○ | T8: ― | U8: ○ | V8: ○ | W8: ― | X8: ― | Y8: ― | Z8: ○ | AA8: ○ | AB8: ○
C9: 量産 | D9: ― | E9: ○ | F9: ○ | G9: ― | H9: ― | I9: ― | J9: ○ | K9: ○ | L9: ― | M9: ○ | N9: ○ | O9: ○ | P9: ― | Q9: ― | R9: ― | S9: ― | T9: ― | U9: ― | V9: ― | W9: ○ | X9: ― | Y9: ― | Z9: ○ | AA9: ○ | AB9: ○
C12: 先週受領の設変
B19: 1
B20: 2
B21: 3
B22: 4
B23: 5
C25: VK11展開会議 来週火曜（A-Gr
C26: 4,5はセット NUT2ケ追加（AAS恒久設変）
C27: 2,3セット SM穴変更NUT追加,2CM変更（VK04の水平展開）
C28: 1は3CM切り欠き対応（7552241383）FRAME品番は7553102010

Sheet 25-45ｰD
A1: No. | B1: ライン | C1: 納入品番1 | D1: 納入品名称 | E1: 基本車型 | F1: 車型名称 | G1: イベント | H1: 荷姿 | I1: 刻印 | J1: 初品区分 | K1: 初品納入日 | L1: 初日台数 | M1: 1025 | N1: 1027 | O1: 1029 | P1: 1030 | Q1: 1031 | R1: 1101 | S1: 1103 | T1: 1104 | U1: 1105 | V1: 1106 | W1: 1107 | X1: 1108 | Y1: 総計
A2: 1 | B2: A | C2: 7552222861 | D2: FRAME ASM | E2: VK00 | F2: VK00 NKR | G2: VK00 B2-GR 一生向け 700幅 設変出図 | H2: ライン | I2: NT1 | J2: 初 | K2: 45961 | L2: 3 | Q2: 3 | Y2: 3
A3: 2 | B3: C | C3: 8978408070 | D3: FRAME ASM | E3: VL20 | F3: VN80 NPR | G3: VL20 H4-GR FRAME ASM、SIDE MEMBER 新規出図 | H3: ライン | I3: W3S | J3: 初 | K3: 45962 | L3: 2 | R3: 2 | T3: 1 | Y3: 3
A4: 3 | B4: A | C4: 7552714200 | D4: FRAME ASM | E4: VL26 | F4: VL26 N*R | G4: VL26 A2-GR 一生 国内特装車FRAME ASM、SIDE MEMBER新規出図 | H4: ライン | J4: 初 | K4: 45964 | L4: 1 | S4: 1 | Y4: 1
A5: 4 | B5: A | C5: 7552222851 | D5: FRAME ASM | E5: VK00 | F5: VK00 NKR | G5: VK00 B2-GR 一生向け 700幅 設変出図 | H5: ライン | J5: 初 | K5: 45965 | L5: 2 | T5: 2 | Y5: 2
A6: 5 | B6: A | C6: 8978820134 | D6: FRAME ASM | E6: VL26 | F6: VL26 NPR | G6: I4JLC80VL26 A1-GR 1～3X FRAME ASM 量産設変出図 | H6: ライン | I6: SGM | J6: 初 | K6: 45965 | L6: 1 | T6: 1 | U6: 1 | Y6: 2
A7: 6 | B7: A | C7: 7552703000 | D7: FRAME ASM | E7: NMR | F7: NMR | G7: VK05 A-GR 欧州/トルコ/UK向け 新規出図 | H7: KD | J7: 初 | K7: 45965 | L7: 6 | T7: 6 | Y7: 6
A8: 7 | B8: A | C8: 7552127033 | D8: FRAME ASM | E8: VK00 | F8: VK00 NPR | G8: VK00 B-GR アース位置の不具合設変I4K6681 | H8: ライン | I8: 1RSJ | J8: 初 | K8: 45966 | L8: 1 | U8: 1 | Y8: 1
A9: 8 | B9: A | C9: 7552222871 | D9: FRAME ASM | E9: VK00 | F9: VK00 NKR | G9: VK00 B2-GR 一生向け 700幅 設変出図 | H9: ライン | I9: GF8 | J9: 初 | K9: 45967 | L9: 2 | V9: 2 | Y9: 2
A10: 9 | B10: 115 | C10: 7552998370 | D10: FRAME ASM | E10: VK05 | F10: VK05 NKR | G10: VK05 E-GR K研向け新規出図 | H10: KD | J10: 初 | K10: 45961 | L10: 1 | Q10: 1 | Y10: 1
A11: 10 | B11: 115 | C11: 7552998380 | D11: FRAME ASM | E11: VK05 | F11: VK05 NKR | G11: VK05 E-GR K研向け新規出図 | H11: KD | J11: 初 | K11: 45961 | L11: 1 | Q11: 1 | Y11: 1
A12: 11 | B12: C | C12: 7552472860 | D12: FRAME ASM | E12: VK05 | F12: VK05 NPR | G12: VK05 E-GR K研向け新規出図 | H12: KD | J12: 初 | K12: 45961 | L12: 1 | Q12: 1 | Y12: 1
A13: 12 | B13: C | C13: 7552472980 | D13: FRAME ASM | E13: VK05 | F13: VK05 NPR | G13: VK05 E-GR K研向け新規出図 | H13: KD | J13: 初 | K13: 45961 | L13: 1 | Q13: 1 | Y13: 1
A14: 13 | B14: C | C14: 7552943260 | D14: FRAME ASM | E14: VK05 | F14: VK05 NP* | G14: VK05 E-GR K研向け新規出図 | H14: KD | I14: HL5 | J14: 初 | K14: 45961 | L14: 1 | Q14: 1 | Y14: 1
A15: 14 | B15: A | C15: 7552043232 | D15: FRAME ASM | E15: VK00 | F15: VK00 NPR | G15: 久しぶり | H15: ライン | I15: 1RSE | J15: 久 | K15: 45961 | L15: 4 | Q15: 4 | T15: 4 | U15: 4 | Y15: 12
A16: 15 | B16: A | C16: 8977943522 | D16: FRAME ASM | E16: VK00 | F16: VK00 NKR | G16: 久しぶり | H16: ライン | I16: LEP | J16: 久 | K16: 45961 | L16: 1 | Q16: 1 | Y16: 1
A17: 16 | B17: C | C17: 8978431090 | D17: FRAME ASM | E17: VL20 | F17: VL20 NQR | G17: 久しぶり | H17: ライン | I17: W6B | J17: 久 | K17: 45961 | L17: 1 | Q17: 1 | S17: 1 | T17: 1 | V17: 2 | W17: 2 | Y17: 7
A18: 17 | B18: A | C18: 8975159601 | D18: FRAME ASM | E18: VL01 | F18: VL01 NPR | G18: 久しぶり | H18: ライン | I18: RFF | J18: 久 | K18: 45962 | L18: 1 | R18: 1 | Y18: 1
A19: 18 | B19: B | C19: 8976723191 | D19: FRAME ASM | E19: VL20 | F19: VL20 NMR | G19: 久しぶり | H19: ライン | I19: A07 | J19: 久 | K19: 45962 | L19: 2 | R19: 2 | Y19: 2
A20: 19 | B20: C | C20: 7551960820 | D20: FRAME ASM | E20: VL34 | F20: VL34 NPR | G20: 久しぶり | H20: ライン | I20: WSV | J20: 久 | K20: 45962 | L20: 1 | R20: 1 | Y20: 1
A21: 20 | B21: C | C21: 8976682221 | D21: FRAME ASM | E21: VL24 | F21: VL24 NPR | G21: 久しぶり | H21: ライン | I21: 1WBB | J21: 久 | K21: 45962 | L21: 1 | R21: 1 | T21: 1 | U21: 1 | Y21: 3
A22: 21 | B22: A | C22: 8977943244 | D22: FRAME ASM | E22: VK00 | F22: VK00 NKR | G22: 久しぶり | H22: ライン | I22: NC6 | J22: 久 | K22: 45965 | L22: 1 | T22: 1 | Y22: 1
A23: 22 | B23: A | C23: 8978794713 | D23: FRAME ASM | E23: VK00 | F23: VK00 NPR | G23: 久しぶり | H23: ライン | I23: 1SLF | J23: 久 | K23: 45965 | L23: 1 | T23: 1 | U23: 1 | V23: 1 | Y23: 3
A24: 23 | B24: C | C24: 8974996990 | D24: FRAME ASM | E24: VL01 | F24: VL01 NPR | G24: 久しぶり | H24: ライン | I24: WAD | J24: 久 | K24: 45965 | L24: 1 | T24: 1 | Y24: 1
A25: 24 | B25: A | C25: 7552043212 | D25: FRAME ASM | E25: VK00 | F25: VK00 NPR | G25: 久しぶり | H25: ライン | I25: 1RSC | J25: 久 | K25: 45966 | L25: 1 | U25: 1 | Y25: 1
A26: 25 | B26: C | C26: 8974997000 | D26: FRAME ASM | E26: VL01 | F26: VL01 NPR | G26: 久しぶり | H26: ライン | I26: WAC | J26: 久 | K26: 45966 | L26: 1 | U26: 1 | Y26: 1
A27: 26 | B27: C | C27: 8976674360 | D27: FRAME ASM | E27: VL20 | F27: VL20 NPR | G27: 久しぶり | H27: ライン | I27: W3L | J27: 久 | K27: 45966 | L27: 1 | U27: 1 | V27: 1 | Y27: 2
A28: 27 | B28: C | C28: 7551960720 | D28: FRAME ASM | E28: VL34 | F28: VL34 NPR | G28: 久しぶり | H28: ライン | I28: W4C | J28: 久 | K28: 45968 | L28: 1 | W28: 1 | Y28: 1
A29: 28 | B29: C | C29: 7552434110 | D29: FRAME ASM | E29: VL37 | F29: VL37 NPR | G29: 久しぶり | H29: KD | I29: YE6 | J29: 久 | K29: 1031 | L29: 6 | Q29: 6 | Y29: 6
A30: 29 | B30: C | C30: 7552434130 | D30: FRAME ASM | E30: VL37 | F30: VL37 NPR | G30: 久しぶり | H30: KD | I30: YSF | J30: 久 | K30: 1031 | L30: 6 | Q30: 6 | T30: 18 | U30: 18 | V30: 12 | Y30: 54
A31: 30 | B31: C | C31: 7552434150 | D31: FRAME ASM | E31: VL37 | F31: VL37 NPR | G31: 久しぶり | H31: KD | I31: YSG | J31: 久 | K31: 1031 | L31: 6 | Q31: 6 | S31: 6 | T31: 12 | U31: 12 | V31: 12 | Y31: 48
A32: 31 | B32: C | C32: 7552434100 | D32: FRAME ASM | E32: VL37 | F32: VL37 NPR | G32: 久しぶり | H32: KD | I32: YAB | J32: 久 | K32: 1103 | L32: 12 | S32: 12 | Y32: 12

Sheet 25-44-D
A1: No. | B1: ライン | C1: 納入品番1 | D1: 納入品名称 | E1: 基本車型 | F1: 車型名称 | G1: イベント | H1: 荷姿 | I1: 刻印 | J1: 初品区分 | K1: 初品納入日 | L1: 初日台数 | M1: 1021 | N1: 1023 | O1: 1024 | P1: 1025 | Q1: 1027 | R1: 1028 | S1: 1029 | T1: 1030 | U1: 1031 | V1: 総計
A2: 2 | B2: A | C2: 7552127213 | D2: FRAME ASM | E2: VK00 | F2: VK00 NPR | G2: I4K6681VK00 B-GR アース位置の不具合設変 | H2: 1 | I2: 1RWD | J2: 初 | K2: 45960 | L2: 1 | T2: 1 | V2: 1
A3: 1 | B3: 115 | C3: 7552208252 | D3: FRAME ASM | E3: VK04 | F3: VK04 NKR | G3: I4K5796VK04 A2-GR 1生向け設変出図 | H3: 1 | J3: 初 | K3: 45960 | L3: 1 | T3: 1 | V3: 1
A4: 3 | B4: A | C4: 7552208121 | D4: FRAME ASM | E4: VK04 | F4: VK04 NKR | G4: VK04 A2-GR 1生向け設変出図 | H4: 1 | J4: 初 | K4: 45960 | L4: 1 | T4: 1 | V4: 1
A5: 4 | B5: A | C5: 7552225631 | D5: FRAME ASM | E5: VK04 | F5: VK04 NMR | G5: I4K5796VK04 A2-GR 1生向け設変出図 | H5: 1 | J5: 初 | K5: 45960 | L5: 1 | T5: 1 | V5: 1
A6: 5 | B6: A | C6: 7552264431 | D6: FRAME ASM | E6: VK04 | F6: VK04 NPR | G6: VK04 A2-GR SOP向け設変出図 | H6: 1 | J6: 初 | K6: 45960 | L6: 2 | T6: 2 | V6: 2
A7: 6 | B7: A | C7: 7552043252 | D7: FRAME ASM | E7: VK00 | F7: VK00 NPR | G7: 久しぶり | H7: 1 | I7: 1RSF | J7: 久 | K7: 45955 | L7: 1 | P7: 1 | S7: 2 | V7: 3
A8: 7 | B8: A | C8: 8977943244 | D8: FRAME ASM | E8: VK00 | F8: VK00 NKR | G8: 久しぶり | H8: 1 | I8: NC6 | J8: 久 | K8: 45955 | L8: 1 | P8: 1 | V8: 1
A9: 8 | B9: C | C9: 7551960580 | D9: FRAME ASM | E9: VL34 | F9: VL34 NPR | G9: 久しぶり | H9: 1 | I9: WWZ | J9: 久 | K9: 45955 | L9: 1 | P9: 1 | R9: 1 | S9: 1 | T9: 1 | V9: 4
A10: 9 | B10: C | C10: 7552138902 | D10: FRAME ASM | E10: VK00 | F10: VK00 NPR | G10: 久しぶり | H10: 1 | I10: HM5 | J10: 久 | K10: 45955 | L10: 1 | P10: 1 | R10: 2 | S10: 1 | T10: 1 | V10: 5
A11: 10 | B11: C | C11: 8974996990 | D11: FRAME ASM | E11: VL01 | F11: VL01 NPR | G11: 久しぶり | H11: 1 | I11: WAD | J11: 久 | K11: 45955 | L11: 1 | P11: 1 | Q11: 1 | T11: 1 | V11: 3
A12: 11 | B12: C | C12: 8977917721 | D12: FRAME ASM | E12: VL20 | F12: VL20 NQR | G12: 久しぶり | H12: 1 | I12: 1WGR | J12: 久 | K12: 45955 | L12: 2 | P12: 2 | Q12: 1 | R12: 2 | S12: 3 | T12: 2 | V12: 10
A13: 12 | B13: A | C13: 7551909950 | D13: FRAME ASM | E13: VK00 | F13: VK00 NKR | G13: 久しぶり | H13: 1 | I13: LER | J13: 久 | K13: 45958 | L13: 2 | R13: 2 | V13: 2
A14: 13 | B14: B | C14: 8976720222 | D14: FRAME ASM | E14: VL20 | F14: VL20 NMR | G14: 久しぶり | H14: 1 | I14: B01 | J14: 久 | K14: 45958 | L14: 1 | R14: 1 | T14: 1 | V14: 2
A15: 14 | B15: C | C15: 8974997000 | D15: FRAME ASM | E15: VL01 | F15: VL01 NPR | G15: 久しぶり | H15: 1 | I15: WAC | J15: 久 | K15: 45958 | L15: 1 | R15: 1 | S15: 1 | V15: 2
A16: 15 | B16: C | C16: 7552418042 | D16: FRAME ASM | E16: VK00 | F16: VK00 NP* | G16: 久しぶり | H16: 3 | I16: HF4 | J16: 久 | K16: 45958 | L16: 6 | R16: 6 | V16: 6
A17: 16 | B17: C | C17: 8976674360 | D17: FRAME ASM | E17: VL20 | F17: VL20 NPR | G17: 久しぶり | H17: 1 | I17: W3L | J17: 久 | K17: 45959 | L17: 1 | S17: 1 | T17: 1 | V17: 2
A18: 17 | B18: C | C18: 7552434110 | D18: FRAME ASM | E18: VL37 | F18: VL37 NPR | H18: 3 | I18: YE6 | J18: 久 | K18: 1024 | L18: 6 | O18: 6 | Q18: 6 | R18: 6 | S18: 6 | T18: 6 | V18: 30
A19: 18 | B19: C | C19: 7552434130 | D19: FRAME ASM | E19: VL37 | F19: VL37 NPR | H19: 3 | I19: YSF | J19: 久 | K19: 1024 | L19: 6 | O19: 6 | V19: 6
A20: 19 | B20: C | C20: 7552434150 | D20: FRAME ASM | E20: VL37 | F20: VL37 NPR | H20: 3 | I20: YSG | J20: 久 | K20: 1027 | L20: 6 | Q20: 6 | R20: 6 | S20: 6 | T20: 6 | V20: 24
A21: 20 | B21: C | C21: 7552434200 | D21: FRAME ASM | E21: VL37 | F21: VL37 NQR | H21: 3 | I21: YSE | J21: 久 | K21: 1028 | L21: 6 | R21: 6 | V21: 6

Sheet 25-43-D
A1: No. | B1: ライン | C1: 納入品番1 | D1: 納入品名称 | E1: 基本車型 | F1: 車型名称 | G1: イベント | H1: 荷姿 | I1: 刻印 | J1: 初品区分 | K1: 初品納入日 | L1: 初日台数 | M1: 1010 | N1: 1015 | O1: 1016 | P1: 1017 | Q1: 1018 | R1: 1020 | S1: 1021 | T1: 1022 | U1: 1023 | V1: 1024 | W1: 総計
A2: 1 | B2: A | C2: 7552701741 | D2: FRAME ASM | E2: VK05 | F2: VK05 NMR | G2: VK05 E-GR K研向け新規出図 | H2: 1 | J2: 初 | K2: 45946 | L2: 1 | O2: 1 | W2: 1
A3: 2 | B3: A | C3: 7552701841 | D3: FRAME ASM | E3: VK05 | F3: VK05 NMR | G3: VK05 E-GR K研向け新規出図 | H3: 1 | J3: 初 | K3: 45946 | L3: 1 | O3: 1 | W3: 1
A4: 3 | B4: C | C4: 7552164981 | D4: FRAME ASM | E4: VK00 | F4: VK00 NP* | G4: VK05 E-GR K研向け新規出図 | H4: 1 | I4: HF9 | J4: 初 | K4: 45946 | L4: 1 | O4: 1 | W4: 1
A5: 4 | B5: C | C5: 7552472910 | D5: FRAME ASM | E5: VK05 | F5: VK05 N** | G5: VK05 E-GR K研向け新規出図 | H5: 1 | J5: 初 | K5: 45946 | L5: 1 | O5: 1 | W5: 1
A6: 5 | B6: C | C6: 7552473040 | D6: FRAME ASM | E6: VK05 | F6: VK05 NPR | G6: VK05 E-GR K研向け新規出図 | H6: 1 | J6: 初 | K6: 45946 | L6: 1 | O6: 1 | W6: 1
A7: 6 | B7: C | C7: 7552943190 | D7: FRAME ASM | E7: VK05 | F7: VK05 NP* | G7: VK05 E-GR K研向け新規出図 | H7: 1 | J7: 初 | K7: 45946 | L7: 1 | O7: 1 | W7: 1
A8: 7 | B8: C | C8: 7552943230 | D8: FRAME ASM | E8: VK05 | F8: VK05 NP* | G8: VK05 E-GR K研向け新規出図 | H8: 1 | J8: 初 | K8: 45946 | L8: 1 | O8: 1 | W8: 1
A9: 8 | B9: C | C9: 7552943260 | D9: FRAME ASM | E9: VK05 | F9: VK05 NP* | G9: VK05 E-GR K研向け新規出図 | H9: 1 | J9: 初 | K9: 45946 | L9: 1 | O9: 1 | W9: 1
A10: 9 | B10: 115 | C10: 7552702980 | D10: FRAME ASM | E10: NMR | F10: VK00 NMR | G10: VK00 F-Gr SOP/VK05 A-GR 欧州/トルコ/UK向け 新規出図 | H10: 3 | I10: DBV | J10: 初 | K10: 45947 | L10: 24 | P10: 24 | R10: 24 | S10: 18 | T10: 18 | U10: 12 | W10: 96
A11: 10 | B11: 115 | C11: 7552703020 | D11: FRAME ASM | E11: NMR | F11: NMR | G11: VK00 F-Gr SOP/VK04 A2-GR SOP向け設変出図 | H11: 3 | I11: FBD | J11: 初 | K11: 45947 | L11: 6 | P11: 6 | T11: 12 | U11: 6 | W11: 24
A12: 11 | B12: A | C12: 8972681154 | D12: FRAME ASM | E12: VK04 | F12: VK04 NPS | G12: VK04 A1-GR 4*4 量産向け設変出図 | H12: 1 | I12: THA | J12: 初 | K12: 45948 | L12: 2 | Q12: 2 | W12: 2
A13: 12 | B13: 115 | C13: 7552702990 | D13: FRAME ASM | E13: NMR | F13: VK00 NMR | G13: VK00 F-Gr SOP/VK04 A2-GR SOP向け設変出図 | H13: 3 | I13: EAK | J13: 初 | K13: 45950 | L13: 6 | R13: 6 | S13: 18 | T13: 6 | U13: 12 | W13: 42
A14: 13 | B14: A | C14: 7552127213 | D14: FRAME ASM | E14: VK00 | F14: VK00 NPR | G14: I4K6681VK00 B-GR アース位置の不具合設変 | H14: 1 | I14: 1RWD | J14: 初 | K14: 45951 | L14: 1 | S14: 1 | T14: 1 | U14: 1 | W14: 3
A15: 14 | B15: 115 | C15: 7552702920 | D15: FRAME ASM | E15: VK05 | F15: VK05 | G15: VK00 F-Gr SOP/VK05 A-GR | H15: 3 | I15: DBU | J15: 初 | K15: 45953 | L15: 6 | U15: 6 | W15: 6
A16: 15 | B16: A | C16: 7552127064 | D16: FRAME ASM | E16: VK00 | F16: VK00 NPR | G16: I4K6681VK00 B-GR アース位置の不具合設変 | H16: 1 | I16: 1SGS | J16: 初 | K16: 45954 | L16: 3 | V16: 3 | W16: 3
A17: 17 | B17: C | C17: 8978836721 | D17: FRAME ASM | E17: VK00 | F17: VK00 NP* | G17: 久しぶり | H17: 3 | I17: HF6 | J17: 久 | K17: 45947 | L17: 6 | P17: 6 | W17: 6
A18: 18 | B18: A | C18: 7551909300 | D18: FRAME ASM | E18: VK00 | F18: VK00 NKR | G18: 久しぶり | H18: 1 | I18: CHE | J18: 久 | K18: 45948 | L18: 1 | Q18: 1 | W18: 1
A19: 19 | B19: A | C19: 8978739152 | D19: FRAME ASM | E19: VK00 | F19: VK00 NKR | G19: 久しぶり | H19: 1 | I19: PW2 | J19: 久 | K19: 45948 | L19: 1 | Q19: 1 | R19: 1 | S19: 1 | V19: 1 | W19: 4
A20: 20 | B20: C | C20: 8972416592 | D20: FRAME ASM | E20: VK00 | F20: VK00 NPR | G20: 久しぶり | H20: 1 | I20: ZTL | J20: 久 | K20: 45948 | L20: 1 | Q20: 1 | T20: 2 | W20: 3
A21: 21 | B21: A | C21: 7551885502 | D21: FRAME ASM | E21: VK00 | F21: VK00 NPR | G21: 久しぶり | H21: 1 | I21: 1RSB | J21: 久 | K21: 45951 | L21: 2 | S21: 2 | W21: 2
A22: 22 | B22: A | C22: 8977943322 | D22: FRAME ASM | E22: VK00 | F22: VK00 NKR | G22: 久しぶり | H22: 1 | I22: KA3 | J22: 久 | K22: 45951 | L22: 1 | S22: 1 | T22: 1 | W22: 2
A23: 23 | B23: C | C23: 8984857951 | D23: FRAME ASM | E23: VL01 | F23: VL01 NPR | G23: 久しぶり | H23: 1 | I23: 1WQH | J23: 久 | K23: 45951 | L23: 1 | S23: 1 | W23: 1
A24: 25 | B24: 115 | C24: 8975047131 | D24: FRAME ASM | E24: NKR | F24: VL11 NKR | G24: 久しぶり | H24: 1 | I24: DE2 | J24: 久 | K24: 45952 | L24: 1 | T24: 1 | U24: 1 | W24: 2
A25: 26 | B25: C | C25: 7552434130 | D25: FRAME ASM | E25: VL37 | F25: VL37 NPR | G25: 久しぶり | H25: 3 | I25: YSF | J25: 久 | K25: 45953 | L25: 24 | U25: 24 | W25: 24
A26: 16 | B26: C | C26: 7552434150 | D26: FRAME ASM | E26: VL37 | F26: VL37 NPR | G26: 久しぶり | H26: 3 | I26: YSG | J26: 久 | K26: 45947 | L26: 6 | P26: 6 | R26: 6 | S26: 12 | T26: 6 | U26: 12 | W26: 42
A27: 24 | B27: C | C27: 7552434110 | D27: FRAME ASM | E27: VL37 | F27: VL37 NPR | G27: 久しぶり | H27: 3 | I27: YE6 | J27: 久 | K27: 45951 | L27: 6 | S27: 6 | T27: 6 | W27: 12

Sheet 25-42-D
A1: No. | B1: ライン | C1: 納入品番1 | D1: 納入品名称 | E1: 基本車型 | F1: 車型名称 | G1: イベント | H1: 荷姿 | I1: 刻印 | J1: 初品区分 | K1: 初品納入日 | L1: 初日台数 | M1: 1006 | N1: 1008 | O1: 1009 | P1: 1010 | Q1: 1011 | R1: 1014 | S1: 1015 | T1: 1016 | U1: 1017 | V1: 1018 | W1: 総計
A2: 1 | B2: A | C2: 7552701451 | D2: FRAME ASM | E2: VK05 | F2: VK05 NMR | G2: I4K6545VK05 A,B,C-GR 1生向け設変出図 | H2: 1 | J2: 初 | K2: 45938 | L2: 1 | N2: 1 | W2: 1
A3: 2 | B3: A | C3: 7552701551 | D3: FRAME ASM | E3: VK05 | F3: VK05 NMR | G3: I4K6545VK05 A,B,C-GR 1生向け設変出図 | H3: 1 | J3: 初 | K3: 45938 | L3: 1 | N3: 1 | W3: 1
A4: 3 | B4: A | C4: 7552701661 | D4: FRAME ASM | E4: VK05 | F4: VK05 NMR | G4: I4K6545VK05 A,B,C-GR 1生向け設変出図 | H4: 1 | J4: 初 | K4: 45938 | L4: 1 | N4: 1 | W4: 1
A5: 4 | B5: A | C5: 7552701811 | D5: FRAME ASM | E5: VK05 | F5: VK05 NMR | G5: I4K6545VK05 A,B,C-GR 1生向け設変出図 | H5: 1 | J5: 初 | K5: 45938 | L5: 1 | N5: 1 | W5: 1
A6: 5 | B6: C | C6: 7552165742 | D6: FRAME ASM | E6: VK00 | F6: VK00 NP* | G6: VK00 3X 850幅 B1-GR FRAME ASM 設変出図 | H6: 1 | I6: HK3 | J6: 初 | K6: 45938 | L6: 1 | N6: 1 | W6: 1
A7: 6 | B7: C | C7: 7552418151 | D7: FRAME ASM | E7: VK00 | F7: VK00 NP* | G7: VK00 3X 850幅 B1-GR FRAME ASM 設変出図 | H7: 1 | I7: HKB | J7: 初 | K7: 45938 | L7: 1 | N7: 1 | W7: 1
A8: 7 | B8: C | C8: 7552418181 | D8: FRAME ASM | E8: VK00 | F8: VK00 NP* | G8: VK00 3X 850幅 B1-GR FRAME ASM 設変出図 | H8: 1 | I8: HK6 | J8: 初 | K8: 45938 | L8: 1 | N8: 1 | W8: 1
A9: 8 | B9: C | C9: 7552942710 | D9: FRAME ASM | E9: VK05 | F9: VK05 NP* | G9: VK05 E-GR K研向け新規出図 | H9: 1 | I9: HFD | J9: 初 | K9: 45938 | L9: 1 | N9: 1 | W9: 1
A10: 9 | B10: C | C10: 7552942720 | D10: FRAME ASM | E10: VK05 | F10: VK05 NP* | G10: VK05 E-GR K研向け新規出図 | H10: 1 | I10: HFE | J10: 初 | K10: 45938 | L10: 1 | N10: 1 | W10: 1
A11: 10 | B11: 115 | C11: 7552702920 | D11: FRAME ASM | E11: VK05 | F11: VK05 | G11: VK00 F-Gr SOP | H11: 3 | I11: DBU | J11: 初 | K11: 45939 | L11: 6 | O11: 6 | S11: 18 | T11: 24 | W11: 48
A12: 11 | B12: 115 | C12: 7552702980 | D12: FRAME ASM | E12: NMR | F12: VK00 NMR | G12: VK00 F-Gr SOP | H12: 3 | I12: DBV | J12: 初 | K12: 45939 | L12: 12 | O12: 12 | R12: 12 | S12: 12 | T12: 12 | W12: 48
A13: 12 | B13: 115 | C13: 7552703020 | D13: FRAME ASM | E13: NMR | F13: NMR | G13: VK00 F-Gr SOP | H13: 3 | I13: FBD | J13: 初 | K13: 45939 | L13: 6 | O13: 6 | S13: 6 | W13: 12
A14: 13 | B14: 115 | C14: 7552702990 | D14: FRAME ASM | E14: NMR | F14: VK00 NMR | G14: VK00 F-Gr SOP | H14: 3 | I14: EAK | J14: 初 | K14: 45940 | L14: 18 | P14: 18 | W14: 18
A15: 14 | B15: A | C15: 7552127064 | D15: FRAME ASM | E15: VK00 | F15: VK00 NPR | G15: I4K6681VK00 B-GR アース位置の不具合設変 | H15: 1 | I15: 1SGS | J15: 初 | K15: 45940 | L15: 1 | P15: 1 | U15: 2 | W15: 3
A16: 15 | B16: A | C16: 7552338503 | D16: FRAME ASM | E16: VK00 | F16: VK00 NPR | G16: I4K6792VK00(EXP)B2-GR 量産向け設変出図 | H16: 1 | J16: 初 | K16: 45940 | L16: 1 | P16: 1 | W16: 1
A17: 16 | B17: A | C17: 8978795003 | D17: FRAME ASM | E17: VK04 | F17: VK04 NPS | G17: I4K6626VK04 A1/A2-GR 1生向け設変出図 | H17: 1 | I17: TN4 | J17: 初 | K17: 45940 | L17: 1 | P17: 1 | W17: 1
A18: 17 | B18: A | C18: 7552127023 | D18: FRAME ASM | E18: VK00 | F18: VK00 NPR | G18: I4K6681VK00 B-GR アース位置の不具合設変 | H18: 1 | I18: 1SCQ | J18: 初 | K18: 45946 | L18: 1 | T18: 1 | W18: 1
A19: 18 | B19: A | C19: 8978794824 | D19: FRAME ASM | E19: VK00 | F19: VK00 NPR | G19: 久しぶり | H19: 1 | I19: 1RZ2 | J19: 久 | K19: 45940 | L19: 1 | P19: 1 | U19: 1 | W19: 2
A20: 19 | B20: A | C20: 8978843392 | D20: FRAME ASM | E20: VK00 | F20: VK00 NKR | G20: 久しぶり | H20: 1 | I20: JHF | J20: 久 | K20: 45940 | L20: 1 | P20: 1 | W20: 1
A21: 20 | B21: C | C21: 8972416592 | D21: FRAME ASM | E21: VK00 | F21: VK00 NPR | G21: 久しぶり | H21: 1 | I21: ZTL | J21: 久 | K21: 45940 | L21: 2 | P21: 2 | S21: 2 | W21: 4
A22: 21 | B22: 115 | C22: 8977940183 | D22: FRAME ASM | E22: VK04 | F22: VK04 NKR | G22: 久しぶり | H22: 1 | I22: DAZ | J22: 久 | K22: 45941 | L22: 1 | Q22: 1 | W22: 1
A23: 22 | B23: A | C23: 8977943322 | D23: FRAME ASM | E23: VK00 | F23: VK00 NKR | G23: 久しぶり | H23: 1 | I23: KA3 | J23: 久 | K23: 45941 | L23: 1 | Q23: 1 | S23: 1 | W23: 2
A24: 23 | B24: A | C24: 8977944063 | D24: FRAME ASM | E24: VK00 | F24: VK00 NMR | G24: 久しぶり | H24: 1 | I24: KHG | J24: 久 | K24: 45945 | L24: 1 | S24: 1 | U24: 1 | W24: 2
A25: 24 | B25: A | C25: 8978794554 | D25: FRAME ASM | E25: VK00 | F25: VK00 NPR | G25: 久しぶり | H25: 1 | I25: 1RGK | J25: 久 | K25: 45945 | L25: 1 | S25: 1 | W25: 1
A26: 25 | B26: A | C26: 7551885852 | D26: FRAME ASM | E26: VK00 | F26: VK00 NPR | G26: 久しぶり | H26: 1 | I26: 1RW8 | J26: 久 | K26: 45946 | L26: 1 | T26: 1 | W26: 1
A27: 26 | B27: A | C27: 7551909350 | D27: FRAME ASM | E27: VK00 | F27: VK00 NKR | G27: 久しぶり | H27: 1 | I27: BB1 | J27: 久 | K27: 45947 | L27: 1 | U27: 1 | W27: 1
A28: 27 | B28: A | C28: 7551910010 | D28: FRAME ASM | E28: VK00 | F28: VK00 NMR | G28: 久しぶり | H28: 1 | I28: CMM | J28: 久 | K28: 45947 | L28: 1 | U28: 1 | W28: 1
A29: 28 | B29: C | C29: 7552434130 | D29: FRAME ASM | E29: VL37 | F29: VL37 NPR | G29: 久しぶり | H29: 3 | I29: YSF | J29: 久 | K29: 1010 | L29: 6 | P29: 6 | W29: 6
A30: 29 | B30: C | C30: 7552434150 | D30: FRAME ASM | E30: VL37 | F30: VL37 NPR | G30: 久しぶり | H30: 3 | I30: YSG | J30: 久 | K30: 1014 | L30: 12 | R30: 12 | S30: 6 | T30: 6 | W30: 24

Sheet Monthly 日程1006
S1: ■PPC | X1: ■PPC | AB1: ■PPC | AF1: ■PPC | AJ1: ■PPC | AO1: ■PPC | AS1: ■PPC | AW1: ■PPC | BA1: ■PPC
Q2: 期末 | W2: ☆MC会議 | AA2: ☆MC会議 | AE2: ☆MC会議 | AI2: ☆MC会議 | AL2: 艤装再編SOP | AN2: ☆MC会議 | AQ2: 期末 | AR2: ☆MC会議 | AV2: ☆MC会議 | AZ2: ☆MC会議 | BE2: ■MC会議 | BJ2: ■MC会議 | BN2: ■MC会議 | BR2: ■10/4MC会議 | BV2: ■MC会議 | CA2: ■MC会議 | CF2: ■MC会議 | CJ2: ■MC会議
E4: 2022 | BE4: 2023 | CE4: 2024 | EF4: 2025 | GF4: 2026 | IF4: 2027 | KE4: 2028
E5: 1 | J5: =#REF! -> #REF! | N5: =#REF! -> #REF! | R5: =#REF! -> #REF! | V5: =#REF! -> #REF! | AA5: =#REF! -> #REF! | AE5: =#REF! -> #REF! | AI5: =#REF! -> #REF! | AN5: =#REF! -> #REF! | AR5: =#REF! -> #REF! | AW5: =#REF! -> #REF! | BA5: =#REF! -> #REF! | BE5: 7月 | BJ5: 8月 | BN5: 9月 | BR5: 10月 | BW5: 11月 | CA5: 12月 | CE5: 1月 | CJ5: 2月 | CN5: 3月 | CR5: 4月 | CW5: 5月 | DA5: 6月 | DE5: 7月 | DJ5: 8月 | DN5: 9月 | DS5: 10月 | DW5: 11月 | EA5: 12月 | EF5: １月 | EJ5: 2月 | EN5: 3月 | ES5: 4月 | EW5: ５月 | FA5: 6月 | FF5: 7月 | FJ5: 8月 | FN5: 9月 | FS5: 10月 | FW5: 11月 | GA5: 12月 | GF5: １月 | GJ5: 2月 | GN5: 3月 | GS5: 4月 | GW5: ５月 | HA5: 6月 | HF5: 7月 | HJ5: 8月 | HN5: 9月 | HS5: 10月 | HW5: 11月 | IA5: 12月 | IF5: １月 | IJ5: 2月 | IN5: 3月 | IS5: 4月 | IW5: ５月 | JA5: 6月 | JF5: 7月 | JJ5: 8月 | JN5: 9月 | JS5: 10月 | JW5: 11月 | KA5: 12月 | KE5: 1月
C6: F-Gr
B7: VK00 | C7: RZ4E EUROⅥ | D7: SKD | FU7: SKD
B8: EXP | C8: 欧州 | D8: SUP | GB8: 完成車
CF9: 7 | CG9: 6 | CH9: 5 | CI9: 4 | CJ9: 3 | CK9: 2 | CL9: 1 | CM9: □EPD
B12: VK04 | C12: A1-Gr
C13: 4JZ1 4x4(低床)
C14: RZ4E 4x4(ｼｬｼ認証）
FY23: 未整合
C25: A2-Gr
C27: 4JZ1 4x2
C28: (除く
C29: MZZ、ﾊﾝﾄﾞﾌﾞﾚｰｷ仕様)
C32: 4JZ1 4x2
C33: (MZZ、ﾊﾝﾄﾞﾌﾞﾚｰｷ仕様)
C37: 4JZ1 高型4x4
FY39: 未整合
C41: B-Gr
C42: RZ4E(ベンチ認証)
C43: 4x4(低床)
C48: C-Gr
C49: HEV
C55: D-Gr
C56: ・RZ4E (ｼｬｼ認証）
C57: ４×2
C58: CS・SU対応
C61: VK02
B62: VK02 | C62: B-Gr
C63: 南ア | D63: SKD
C66: VK02 | D66: 完成車
C67: A-Gr | D67: CKD
C68: (UAE,サウジアラビア,バーレーン,クェート,オマーン,カタール) | D68: SKD
C71: VK02
C72: C1/C2-Gr
C73: コロンビア/チリ/ペルー/モロッコ/GCC(ADAS)
C76: VK02 | D76: 完成車
C77: D-Gr
...
