Workbook
Name _______2005_RETAILS_FOR_MITCH_BY_STATE___VIN: #REF!
Name _______2005_RETAILS_FOR_MITCH_BY_STATE___VIN: #REF!
Name _02_CAB機能部品: #REF!
Name _02_CAB部品: #REF!
Name _02_CHASSIS部品: #REF!
Name _1_04_kawaguchi: #REF!
Name _1_2005_RETAILS_FOR_MITCH_BY_STATE___VIN: #REF!
Name _10.00_20_14PR: #REF!
Name _10_Q: #REF!
Name _12.6H: #REF!
Name _13.5H: #REF!
Name _14.5H: #REF!
Name _14_4t_Ð_L: #REF!
Name _15.5H: #REF!
Name _15¿: #REF!
Name _16¼_a: #REF!
Name _17ÔÌÞÚ°·: #REF!
Name _18Ã_¼_a: #REF!
Name _19åÌÞÚ°·: #REF!
Name _1MM: #REF!
Name _1st: #REF!
Name _20ñ___\: #REF!
Name _21ø: #REF!
Name _22À²Ô_²½Þ: #REF!
Name _23ÄÙ¸_\: #REF!
Name _25HS10_: #REF!
Name _26_1生_CROSS_クエリー1: #REF!
Name _26HS11_: #REF!
Name _28_出庫リスト_クエリー: #REF!
Name _2nd: #REF!
Name _3: #REF!
Name _30HS15_: 'Monthly 日程0806'!_30HS15_
Name _30HS15_: [0]!_30HS15_
Name _38HS9_: #REF!
Name _39ÌÞÚ_·_í_Þ: #REF!
Name _3rd: #REF!
Name _4_5t.ÃÞ¨½¸: #REF!
Name _4_5t.STD: #REF!
Name _4_5t.ﾃﾞｨｽｸ: #REF!
Name _4th: #REF!
Name _4t巾広: #REF!
Name _5G: #REF!
Name _5th: #REF!
Name _6HE1_TCN: #REF!
Name _6HE1_TCS: #REF!
Name _6HH1_N: #REF!
Name _6HH1_S: #REF!
Name _6th: #REF!
Name _7t: #REF!
Name _7th: #REF!
Name _8.5_Q: #REF!
Name _8_Q: #REF!
Name _EMD２: 'Monthly 日程0806'!_EMD２
Name _EMD２: [0]!_EMD２
Name _HAN02: #REF!
Name _HAN02: #REF!
Name _HAN03: #REF!
Name _HAN03: #REF!
Name _MC001: #REF!
Name _MC002: #REF!

Sheet 25-38W
AL1: 59 | AM1: 60 | AO1: 64 | AP1: 66 | AQ1: 67
A2: ISZ 週別確定内示リスト（25-38W） | H2: FRAME ASSY | AJ2: Ｆ生産管理課 川﨑
I3: 45915 | J3: =I3+7 -> 45922 | K3: =J3+7 -> 45929 | L3: =K3+7 -> 45936 | M3: =L3+7 -> 45943 | N3: =M3+7 -> 45950 | O3: =N3+7 -> 45957 | P3: =O3+7 -> 45964 | Q3: =P3+7 -> 45971 | ... U3: =T3+7 -> 45999 | W3: VK00B1-Gr NUT数：：\\sv1p000001\藤沢工場\工場向け\P24000(生産管理グループ)\藤沢工場共有フォルダ\企画Ｔｷｬﾋﾞﾈｯﾄ\(07)企画共通\01_小型FRAME\00_プロジェクト\VK00\20250217 輸出 NUT増産進捗確認2\コピー250217_対象品番【850幅】S_MBR構成表_20250214_.xlsx | AG3: OBL 構成 | AH3: 720製造管理システム
A4: No. | B4: ライン | C4: 納入品番1 | D4: 車型名称 | E4: 直近イベント | F4: 荷姿 | G4: 刻印 | H4: 初品区分 | I4: 38W | J4: 39W | K4: 40W | L4: 41W | M4: 42W | N4: 43W | O4: 44W | P4: 45W | Q4: 46W | R4: 47W | S4: 48W | T4: 49W | U4: 50W | V4: 総計 | W4: 納入品名称 | X4: 基本車型 | Y4: 設通NO | Z4: 設通 受領日 | AA4: 受注条件 車型名称 | AB4: イベント車型 | AC4: 送付コメント | AD4: 技計NO | AE4: 生産 ライン | AF4: 刻印 | AH4: 部品ﾋﾟｯｷﾝｸﾞ ﾊﾟﾀｰﾝ検索 | AI4: C/MBR ﾋﾟｯｷﾝｸﾞ ﾏｽﾀ検索 | AP4: 品番貼付け ↓
A5: 46 | C5: 7552338503 | D5: VK00 NPR | E5: I4K6792VK00(EXP)B2-GR 量産向け設変出図 | F5: 1 | H5: 初 | J5: 1 | V5: 1 | W5: FRAME ASM | X5: VK00 | Y5: =VLOOKUP($C5,[1]量産!$C$4:$N$15550,2,FALSE) -> I4K6792 | Z5: =VLOOKUP($C5,[1]量産!$C$4:$N$15550,3,FALSE) -> 45805 | AA5: =VLOOKUP($C5,[1]量産!$C$4:$N$15550,4,FALSE) -> VK00 B2-Gr | AB5: =VLOOKUP($C5,[1]量産!$C$4:$N$15550,5,FALSE) -> VK00 B2-Gr EXP | AC5: =VLOOKUP($C5,[1]量産!$C$4:$N$15550,6,FALSE) -> VK00 B2-Gr EXP量産向け設変出図 | AD5: =VLOOKUP($C5,[1]量産!$C$4:$N$15550,7,FALSE) -> 0 | AE5: =VLOOKUP($C5,[1]量産!$C$4:$N$15550,8,FALSE) -> 0 | AF5: =VLOOKUP($C5,[1]量産!$C$4:$N$15550,9,FALSE) -> 0 | AG5: =VLOOKUP($C5,[1]量産!$C$4:$N$15550,10,FALSE) -> 0 | AH5: =VLOOKUP($C5,[1]量産!$C$4:$N$15550,11,FALSE) -> 0 | AI5: =VLOOKUP($C5,[1]量産!$C$4:$N$15550,12,FALSE) -> 0 | AL5: =C5 -> 7552338503 | AM5: =B5 -> 0 | AN5: =E5 -> I4K6792VK00(EXP)B2-GR 量産向け設変出図 | AP5: 7551885412 | AQ5: =VLOOKUP(AP5,AL5:AM850,2,FALSE) -> A | AR5: =VLOOKUP(AP5,AL5:AN850,3,FALSE) -> 久しぶり | BK5: =VLOOKUP(C:C,[2]Sheet2!$A:$A,1,FALSE) -> #N/A
A6: 47 | C6: 7552473040 | D6: VK05 NPR | E6: I3K6135VK05 E-GR K研向け新規出図 | F6: 1 | H6: 初 | K6: 1 | V6: 1 | W6: FRAME ASM | X6: VK05 | Y6: =VLOOKUP($C6,[1]量産!$C$4:$N$15550,2,FALSE) -> #N/A | Z6: =VLOOKUP($C6,[1]量産!$C$4:$N$15550,3,FALSE) -> #N/A | AA6: =VLOOKUP($C6,[1]量産!$C$4:$N$15550,4,FALSE) -> #N/A | AB6: =VLOOKUP($C6,[1]量産!$C$4:$N$15550,5,FALSE) -> #N/A | AC6: =VLOOKUP($C6,[1]量産!$C$4:$N$15550,6,FALSE) -> #N/A | AD6: =VLOOKUP($C6,[1]量産!$C$4:$N$15550,7,FALSE) -> #N/A | AE6: =VLOOKUP($C6,[1]量産!$C$4:$N$15550,8,FALSE) -> #N/A | AF6: =VLOOKUP($C6,[1]量産!$C$4:$N$15550,9,FALSE) -> #N/A | AG6: =VLOOKUP($C6,[1]量産!$C$4:$N$15550,10,FALSE) -> #N/A | AH6: =VLOOKUP($C6,[1]量産!$C$4:$N$15550,11,FALSE) -> #N/A | AI6: =VLOOKUP($C6,[1]量産!$C$4:$N$15550,12,FALSE) -> #N/A | AL6: =C6 -> 7552473040 | AM6: =B6 -> 0 | AN6: =E6 -> I3K6135VK05 E-GR K研向け新規出図 | AP6: 7552078350 | AQ6: =VLOOKUP(AP6,AL6:AM860,2,FALSE) -> A | AR6: =VLOOKUP(AP6,AL6:AN860,3,FALSE) -> 久しぶり | BK6: =VLOOKUP(C:C,[2]Sheet2!$A:$A,1,FALSE) -> 7552473040
A7: 44 | C7: 7551909772 | D7: VK04 NMS | E7: I4K6850VK04 A1-GR 1生向け設変出図 | F7: 1 | H7: 初 | L7: 1 | M7: 2 | N7: 2 | O7: 1 | V7: 6 | W7: FRAME ASM | X7: VK04 | Y7: =VLOOKUP($C7,[1]量産!$C$4:$N$15550,2,FALSE) -> I4K5796 | Z7: =VLOOKUP($C7,[1]量産!$C$4:$N$15550,3,FALSE) -> 45770 | AA7: =VLOOKUP($C7,[1]量産!$C$4:$N$15550,4,FALSE) -> VK04 A2-Gr | AB7: =VLOOKUP($C7,[1]量産!$C$4:$N$15550,5,FALSE) -> VK04A2-Gr1SEI | AC7: =VLOOKUP($C7,[1]量産!$C$4:$N$15550,6,FALSE) -> VK04A2-Gr1SEI向け設変出図 | AD7: =VLOOKUP($C7,[1]量産!$C$4:$N$15550,7,FALSE) -> 0 | AE7: =VLOOKUP($C7,[1]量産!$C$4:$N$15550,8,FALSE) -> A | AF7: =VLOOKUP($C7,[1]量産!$C$4:$N$15550,9,FALSE) -> 0 | AG7: =VLOOKUP($C7,[1]量産!$C$4:$N$15550,10,FALSE) -> 0 | AH7: =VLOOKUP($C7,[1]量産!$C$4:$N$15550,11,FALSE) -> 0 | AI7: =VLOOKUP($C7,[1]量産!$C$4:$N$15550,12,FALSE) -> 0 | AL7: =C7 -> 7551909772 | AM7: =B7 -> 0 | AN7: =E7 -> I4K6850VK04 A1-GR 1生向け設変出図 | AP7: 7552701721 | AQ7: =VLOOKUP(AP7,AL7:AM861,2,FALSE) -> A | AR7: =VLOOKUP(AP7,AL7:AN861,3,FALSE) -> I4K6545VK05 A,B,C-GR 1生向け設変出図 | BK7: =VLOOKUP(C:C,[2]Sheet2!$A:$A,1,FALSE) -> #N/A
A8: 45 | C8: 7552166153 | D8: VK00 NPR | E8: I4K5771VK00 B1-GR 850幅 3X SOP 3RD C/M 共締め指示 誤記修正 設変出図(内容：図面・3Dモデルの共締め指示の修正、過去設変の水平展開であるRIVET;ENGINE C/M OUTER BRKTの長さ変更の反映) | F8: 1 | H8: 初 | O8: 1 | P8: 2 | Q8: 2 | R8: 2 | S8: 1 | T8: 2 | U8: 1 | V8: 11 | W8: FRAME ASM | X8: VK00 | Y8: =VLOOKUP($C8,[1]量産!$C$4:$N$15550,2,FALSE) -> I4K5443 | Z8: =VLOOKUP($C8,[1]量産!$C$4:$N$15550,3,FALSE) -> 45551 | AA8: =VLOOKUP($C8,[1]量産!$C$4:$N$15550,4,FALSE) -> VK00 NPR | AB8: =VLOOKUP($C8,[1]量産!$C$4:$N$15550,5,FALSE) -> VK00 B1-GR 850幅 | AC8: =VLOOKUP($C8,[1]量産!$C$4:$N$15550,6,FALSE) -> 【AAS-LD-14622】VK00 B1-GR 850幅 FRAME SOP反映AAS(内容：EPW:24/10/14以降において最新サフィックスへ①～③を反映。①溶接NUT追加、S/M追加穴反映不要②溶接NUT追加及びSTIFF追加、S/M追加穴反映不要、③RIVET削除を反映。 ※追加穴反映については金型での反映可能なタイミングで問題無。) | AD8: =VLOOKUP($C8,[1]量産!$C$4:$N$15550,7,FALSE) -> 0 | AE8: =VLOOKUP($C8,[1]量産!$C$4:$N$15550,8,FALSE) -> 0 | AF8: =VLOOKUP($C8,[1]量産!$C$4:$N$15550,9,FALSE) -> 0 | AG8: =VLOOKUP($C8,[1]量産!$C$4:$N$15550,10,FALSE) -> 未 | AH8: =VLOOKUP($C8,[1]量産!$C$4:$N$15550,11,FALSE) -> 未 | AI8: =VLOOKUP($C8,[1]量産!$C$4:$N$15550,12,FALSE) -> 未 | AL8: =C8 -> 7552166153 | AM8: =B8 -> 0 | AN8: =E8 -> I4K5771VK00 B1-GR 850幅 3X SOP 3RD C/M 共締め指示 誤記修正 設変出図(内容：図面・3Dモデルの共締め指示の修正、過去設変の水平展開であるRIVET;ENGINE C/M OUTER BRKTの長さ変更の反映) | AP8: 7552701731 | AQ8: =VLOOKUP(AP8,AL8:AM862,2,FALSE) -> A | AR8: =VLOOKUP(AP8,AL8:AN862,3,FALSE) -> I4K6545VK05 A,B,C-GR 1生向け設変出図 | BK8: =VLOOKUP(C:C,[2]Sheet2!$A:$A,1,FALSE) -> #N/A
A9: 41 | C9: 8978795013 | D9: VK04 NPS | E9: I4K6626VK04 A1/A2-GR 1生向け設変出図 | F9: 1 | H9: 初 | J9: 1 | O9: 1 | P9: 1 | Q9: 1 | R9: 1 | V9: 5 | W9: FRAME ASM | X9: VK04 | Y9: =VLOOKUP($C9,[1]量産!$C$4:$N$15550,2,FALSE) -> I4K6268 | Z9: =VLOOKUP($C9,[1]量産!$C$4:$N$15550,3,FALSE) -> 45677 | AA9: =VLOOKUP($C9,[1]量産!$C$4:$N$15550,4,FALSE) -> VK04 NPS | AB9: =VLOOKUP($C9,[1]量産!$C$4:$N$15550,5,FALSE) -> VK04 A1-Gr | AC9: =VLOOKUP($C9,[1]量産!$C$4:$N$15550,6,FALSE) -> VK04 A1-Gr 4X4 量産向け設変出図 | AD9: =VLOOKUP($C9,[1]量産!$C$4:$N$15550,7,FALSE) -> 0 | AE9: =VLOOKUP($C9,[1]量産!$C$4:$N$15550,8,FALSE) -> A | AF9: =VLOOKUP($C9,[1]量産!$C$4:$N$15550,9,FALSE) -> 0 | AG9: =VLOOKUP($C9,[1]量産!$C$4:$N$15550,10,FALSE) -> 未 | AH9: =VLOOKUP($C9,[1]量産!$C$4:$N$15550,11,FALSE) -> 未 | AI9: =VLOOKUP($C9,[1]量産!$C$4:$N$15550,12,FALSE) -> 未 | AL9: =C9 -> 8978795013 | AM9: =B9 | AN9: =E9 -> I4K6626VK04 A1/A2-GR 1生向け設変出図 | AP9: 8978845054 | AQ9: =VLOOKUP(AP9,AL9:AM863,2,FALSE) -> A | AR9: =VLOOKUP(AP9,AL9:AN863,3,FALSE) -> VK04 A2-GR 1生向け設変出図 | BK9: =VLOOKUP(C:C,[2]Sheet2!$A:$A,1,FALSE) -> #N/A
A10: 20 | C10: 7552222911 | D10: VK00 NKR | E10: VK00 B2-GR 一生向け 700幅 設変出図(内容:構成部品の最新化、溶接NUT変更) | F10: 1 | H10: 初 | J10: 1 | O10: 1 | P10: 1 | Q10: 1 | R10: 1 | V10: 5 | W10: FRAME ASM | X10: VK00 | Y10: =VLOOKUP($C10,[1]量産!$C$4:$N$15550,2,FALSE) -> I4K5030 | Z10: =VLOOKUP($C10,[1]量産!$C$4:$N$15550,3,FALSE) -> 45450 | AA10: =VLOOKUP($C10,[1]量産!$C$4:$N$15550,4,FALSE) -> VK00 NKR | AB10: =VLOOKUP($C10,[1]量産!$C$4:$N$15550,5,FALSE) -> VK00 B2-Gr 700幅 | AC10: =VLOOKUP($C10,[1]量産!$C$4:$N$15550,6,FALSE) -> VK00 B2-GR 一生向け 700幅 設変出図(内容:構成部品の最新化、溶接NUT変更) | AD10: =VLOOKUP($C10,[1]量産!$C$4:$N$15550,7,FALSE) -> 0 | AE10: =VLOOKUP($C10,[1]量産!$C$4:$N$15550,8,FALSE) -> A | AF10: =VLOOKUP($C10,[1]量産!$C$4:$N$15550,9,FALSE) -> 0 | AG10: =VLOOKUP($C10,[1]量産!$C$4:$N$15550,10,FALSE) -> 未 | AH10: =VLOOKUP($C10,[1]量産!$C$4:$N$15550,11,FALSE) -> 未 | AI10: =VLOOKUP($C10,[1]量産!$C$4:$N$15550,12,FALSE) -> 未 | AL10: =C10 -> 7552222911 | AM10: =B10 | AN10: =E10 -> VK00 B2-GR 一生向け 700幅 設変出図(内容:構成部品の最新化、溶接NUT変更) | AP10: 8983922641 | AQ10: =VLOOKUP(AP10,AL10:AM864,2,FALSE) -> A | AR10: =VLOOKUP(AP10,AL10:AN864,3,FALSE) -> 久しぶり | BK10: =VLOOKUP(C:C,[2]Sheet2!$A:$A,1,FALSE) -> #N/A
A11: 5 | C11: 7552127013 | D11: VK00 NPR | E11: I4K6681VK00 B-GR アース位置の不具合設変 | F11: 1 | H11: 初 | K11: 3 | L11: 11 | M11: 9 | N11: 9 | O11: 7 | P11: 10 | Q11: 11 | R11: 11 | S11: 11 | T11: 10 | U11: 5 | V11: 97 | W11: FRAME ASM | X11: VK00 | Y11: =VLOOKUP($C11,[1]量産!$C$4:$N$15550,2,FALSE) -> I4K6681 | Z11: =VLOOKUP($C11,[1]量産!$C$4:$N$15550,3,FALSE) -> 45797 | AA11: =VLOOKUP($C11,[1]量産!$C$4:$N$15550,4,FALSE) -> VK00 B-Gr | AB11: =VLOOKUP($C11,[1]量産!$C$4:$N$15550,5,FALSE) -> VK00 B-Gr | AC11: =VLOOKUP($C11,[1]量産!$C$4:$N$15550,6,FALSE) -> VK00 B-Gr アース一の不具合設変 | AD11: =VLOOKUP($C11,[1]量産!$C$4:$N$15550,7,FALSE) -> 0 | AE11: =VLOOKUP($C11,[1]量産!$C$4:$N$15550,8,FALSE) -> 0 | AF11: =VLOOKUP($C11,[1]量産!$C$4:$N$15550,9,FALSE) -> 0 | AG11: =VLOOKUP($C11,[1]量産!$C$4:$N$15550,10,FALSE) -> 0 | AH11: =VLOOKUP($C11,[1]量産!$C$4:$N$15550,11,FALSE) -> 0 | AI11: =VLOOKUP($C11,[1]量産!$C$4:$N$15550,12,FALSE) -> 0 | AL11: =C11 -> 7552127013 | AM11: =B11 | AN11: =E11 -> I4K6681VK00 B-GR アース位置の不具合設変 | AP11: 7552418211 | AQ11: =VLOOKUP(AP11,AL11:AM865,2,FALSE) -> C | AR11: =VLOOKUP(AP11,AL11:AN865,3,FALSE) -> VK00 3X 850幅 B1-GR FRAME ASM 設変出図(内容：FRAME ASM内容品最新化,S/M ASM LH 溶接NUT及びSTIFF SUB SPG BRKT追加,RIVET削除,REINF LH 溶接NUT追加) | BK11: =VLOOKUP(C:C,[2]Sheet2!$A:$A,1,FALSE) -> #N/A
A12: 6 | C12: 7552127023 | D12: VK00 NPR | E12: I4K6681VK00 B-GR アース位置の不具合設変 | F12: 1 | H12: 初 | K12: 1 | L12: 3 | M12: 3 | N12: 2 | O12: 1 | P12: 1 | Q12: 3 | R12: 4 | S12: 2 | V12: 20 | W12: FRAME ASM | X12: VK00 | Y12: =VLOOKUP($C12,[1]量産!$C$4:$N$15550,2,FALSE) -> I4K6681 | Z12: =VLOOKUP($C12,[1]量産!$C$4:$N$15550,3,FALSE) -> 45797 | AA12: =VLOOKUP($C12,[1]量産!$C$4:$N$15550,4,FALSE) -> VK00 B-Gr | AB12: =VLOOKUP($C12,[1]量産!$C$4:$N$15550,5,FALSE) -> VK00 B-Gr | AC12: =VLOOKUP($C12,[1]量産!$C$4:$N$15550,6,FALSE) -> VK00 B-Gr アース一の不具合設変 | AD12: =VLOOKUP($C12,[1]量産!$C$4:$N$15550,7,FALSE) -> 0 | AE12: =VLOOKUP($C12,[1]量産!$C$4:$N$15550,8,FALSE) -> A | AF12: =VLOOKUP($C12,[1]量産!$C$4:$N$15550,9,FALSE) -> 0 | AG12: =VLOOKUP($C12,[1]量産!$C$4:$N$15550,10,FALSE) -> 0 | AH12: =VLOOKUP($C12,[1]量産!$C$4:$N$15550,11,FALSE) -> 0 | AI12: =VLOOKUP($C12,[1]量産!$C$4:$N$15550,12,FALSE) -> 0 | AL12: =C12 -> 7552127023 | AM12: =B12 | AN12: =E12 -> I4K6681VK00 B-GR アース位置の不具合設変 | AP12: 7552770110 | AQ12: =VLOOKUP(AP12,AL12:AM869,2,FALSE) -> C | AR12: =VLOOKUP(AP12,AL12:AN869,3,FALSE) -> VK05 A/B-GR K研向け新規出図 | BK12: =VLOOKUP(C:C,[2]Sheet2!$A:$A,1,FALSE) -> #N/A
A13: 8 | C13: 7552127054 | D13: VK00 NPR | E13: I4K6681VK00 B-GR アース位置の不具合設変 | F13: 1 | H13: 初 | K13: 5 | L13: 25 | M13: 18 | N13: 19 | O13: 15 | P13: 22 | Q13: 20 | R13: 19 | S13: 17 | T13: 27 | U13: 22 | V13: 209 | W13: FRAME ASM | X13: VK00 | Y13: =VLOOKUP($C13,[1]量産!$C$4:$N$15550,2,FALSE) -> I4K6681 | Z13: =VLOOKUP($C13,[1]量産!$C$4:$N$15550,3,FALSE) -> 45797 | AA13: =VLOOKUP($C13,[1]量産!$C$4:$N$15550,4,FALSE) -> VK00 B-Gr | AB13: =VLOOKUP($C13,[1]量産!$C$4:$N$15550,5,FALSE) -> VK00 B-Gr | AC13: =VLOOKUP($C13,[1]量産!$C$4:$N$15550,6,FALSE) -> VK00 B-Gr アース一の不具合設変 | AD13: =VLOOKUP($C13,[1]量産!$C$4:$N$15550,7,FALSE) -> 0 | AE13: =VLOOKUP($C13,[1]量産!$C$4:$N$15550,8,FALSE) -> 0 | AF13: =VLOOKUP($C13,[1]量産!$C$4:$N$15550,9,FALSE) -> 0 | AG13: =VLOOKUP($C13,[1]量産!$C$4:$N$15550,10,FALSE) -> 0 | AH13: =VLOOKUP($C13,[1]量産!$C$4:$N$15550,11,FALSE) -> 0 | AI13: =VLOOKUP($C13,[1]量産!$C$4:$N$15550,12,FALSE) -> 0 | AL13: =C13 -> 7552127054 | AM13: =B13 | AN13: =E13 -> I4K6681VK00 B-GR アース位置の不具合設変 | AP13: 7552942680 | AQ13: =VLOOKUP(AP13,AL13:AM870,2,FALSE) -> C | AR13: =VLOOKUP(AP13,AL13:AN870,3,FALSE) -> VK05 A/B-GR K研向け新規出図 | BK13: =VLOOKUP(C:C,[2]Sheet2!$A:$A,1,FALSE) -> #N/A
A14: 9 | C14: 7552127064 | D14: VK00 NPR | E14: I4K6681VK00 B-GR アース位置の不具合設変 | F14: 1 | H14: 初 | K14: 1 | L14: 5 | M14: 4 | N14: 3 | O14: 5 | P14: 10 | Q14: 7 | R14: 5 | S14: 4 | V14: 44 | W14: FRAME ASM | X14: VK00 | Y14: =VLOOKUP($C14,[1]量産!$C$4:$N$15550,2,FALSE) -> I4K6681 | Z14: =VLOOKUP($C14,[1]量産!$C$4:$N$15550,3,FALSE) -> 45797 | AA14: =VLOOKUP($C14,[1]量産!$C$4:$N$15550,4,FALSE) -> VK00 B-Gr | AB14: =VLOOKUP($C14,[1]量産!$C$4:$N$15550,5,FALSE) -> VK00 B-Gr | AC14: =VLOOKUP($C14,[1]量産!$C$4:$N$15550,6,FALSE) -> VK00 B-Gr アース一の不具合設変 | AD14: =VLOOKUP($C14,[1]量産!$C$4:$N$15550,7,FALSE) -> 0 | AE14: =VLOOKUP($C14,[1]量産!$C$4:$N$15550,8,FALSE) -> A | AF14: =VLOOKUP($C14,[1]量産!$C$4:$N$15550,9,FALSE) -> 0 | AG14: =VLOOKUP($C14,[1]量産!$C$4:$N$15550,10,FALSE) -> 0 | AH14: =VLOOKUP($C14,[1]量産!$C$4:$N$15550,11,FALSE) -> 0 | AI14: =VLOOKUP($C14,[1]量産!$C$4:$N$15550,12,FALSE) -> 0 | AL14: =C14 -> 7552127064 | AM14: =B14 | AN14: =E14 -> I4K6681VK00 B-GR アース位置の不具合設変 | AP14: 7552942690 | AQ14: =VLOOKUP(AP14,AL14:AM871,2,FALSE) -> C | AR14: =VLOOKUP(AP14,AL14:AN871,3,FALSE) -> VK05 A/B-GR K研向け新規出図 | BK14: =VLOOKUP(C:C,[2]Sheet2!$A:$A,1,FALSE) -> #N/A
A15: 10 | C15: 7552127094 | D15: VK00 NPR | E15: I4K6681VK00 B-GR アース位置の不具合設変 | F15: 1 | H15: 初 | K15: 3 | L15: 13 | M15: 12 | N15: 11 | O15: 10 | P15: 20 | Q15: 17 | R15: 16 | S15: 16 | T15: 24 | U15: 17 | V15: 159 | W15: FRAME ASM | X15: VK00 | Y15: =VLOOKUP($C15,[1]量産!$C$4:$N$15550,2,FALSE) -> I4K6681 | Z15: =VLOOKUP($C15,[1]量産!$C$4:$N$15550,3,FALSE) -> 45797 | AA15: =VLOOKUP($C15,[1]量産!$C$4:$N$15550,4,FALSE) -> VK00 B-Gr | AB15: =VLOOKUP($C15,[1]量産!$C$4:$N$15550,5,FALSE) -> VK00 B-Gr | AC15: =VLOOKUP($C15,[1]量産!$C$4:$N$15550,6,FALSE) -> VK00 B-Gr アース一の不具合設変 | AD15: =VLOOKUP($C15,[1]量産!$C$4:$N$15550,7,FALSE) -> 0 | AE15: =VLOOKUP($C15,[1]量産!$C$4:$N$15550,8,FALSE) -> 0 | AF15: =VLOOKUP($C15,[1]量産!$C$4:$N$15550,9,FALSE) -> 0 | AG15: =VLOOKUP($C15,[1]量産!$C$4:$N$15550,10,FALSE) -> 0 | AH15: =VLOOKUP($C15,[1]量産!$C$4:$N$15550,11,FALSE) -> 0 | AI15: =VLOOKUP($C15,[1]量産!$C$4:$N$15550,12,FALSE) -> 0 | AL15: =C15 -> 7552127094 | AM15: =B15 | AN15: =E15 -> I4K6681VK00 B-GR アース位置の不具合設変 | AP15: 7552942750 | AQ15: =VLOOKUP(AP15,AL15:AM872,2,FALSE) -> C | AR15: =VLOOKUP(AP15,AL15:AN872,3,FALSE) -> VK05 A/B-GR K研向け新規出図 | BK15: =VLOOKUP(C:C,[2]Sheet2!$A:$A,1,FALSE) -> #N/A
A16: 11 | C16: 7552127155 | D16: VK00 NPR | E16: I4K6681VK00 B-GR アース位置の不具合設変 | F16: 1 | H16: 初 | K16: 2 | L16: 11 | M16: 8 | N16: 9 | O16: 9 | P16: 10 | Q16: 9 | R16: 9 | S16: 7 | T16: 4 | U16: 2 | V16: 80 | W16: FRAME ASM | X16: VK00 | Y16: =VLOOKUP($C16,[1]量産!$C$4:$N$15550,2,FALSE) -> I4K6681 | Z16: =VLOOKUP($C16,[1]量産!$C$4:$N$15550,3,FALSE) -> 45797 | AA16: =VLOOKUP($C16,[1]量産!$C$4:$N$15550,4,FALSE) -> VK00 B-Gr | AB16: =VLOOKUP($C16,[1]量産!$C$4:$N$15550,5,FALSE) -> VK00 B-Gr | AC16: =VLOOKUP($C16,[1]量産!$C$4:$N$15550,6,FALSE) -> VK00 B-Gr アース一の不具合設変 | AD16: =VLOOKUP($C16,[1]量産!$C$4:$N$15550,7,FALSE) -> 0 | AE16: =VLOOKUP($C16,[1]量産!$C$4:$N$15550,8,FALSE) -> A | AF16: =VLOOKUP($C16,[1]量産!$C$4:$N$15550,9,FALSE) -> 0 | AG16: =VLOOKUP($C16,[1]量産!$C$4:$N$15550,10,FALSE) -> 0 | AH16: =VLOOKUP($C16,[1]量産!$C$4:$N$15550,11,FALSE) -> 0 | AI16: =VLOOKUP($C16,[1]量産!$C$4:$N$15550,12,FALSE) -> 0 | AL16: =C16 -> 7552127155 | AM16: =B16 | AN16: =E16 -> I4K6681VK00 B-GR アース位置の不具合設変 | AP16: 7552942950 | AQ16: =VLOOKUP(AP16,AL16:AM873,2,FALSE) -> C | AR16: =VLOOKUP(AP16,AL16:AN873,3,FALSE) -> VK05 A/B-GR K研向け新規出図 | BK16: =VLOOKUP(C:C,[2]Sheet2!$A:$A,1,FALSE) -> #N/A
A17: 12 | C17: 7552127213 | D17: VK00 NPR | E17: I4K6681VK00 B-GR アース位置の不具合設変 | F17: 1 | H17: 初 | K17: 1 | L17: 2 | M17: 2 | N17: 1 | P17: 1 | Q17: 1 | R17: 1 | S17: 1 | T17: 1 | V17: 11 | W17: FRAME ASM | X17: VK00 | Y17: =VLOOKUP($C17,[1]量産!$C$4:$N$15550,2,FALSE) -> I4K6681 | Z17: =VLOOKUP($C17,[1]量産!$C$4:$N$15550,3,FALSE) -> 45797 | AA17: =VLOOKUP($C17,[1]量産!$C$4:$N$15550,4,FALSE) -> VK00 B-Gr | AB17: =VLOOKUP($C17,[1]量産!$C$4:$N$15550,5,FALSE) -> VK00 B-Gr | AC17: =VLOOKUP($C17,[1]量産!$C$4:$N$15550,6,FALSE) -> VK00 B-Gr アース一の不具合設変 | AD17: =VLOOKUP($C17,[1]量産!$C$4:$N$15550,7,FALSE) -> 0 | AE17: =VLOOKUP($C17,[1]量産!$C$4:$N$15550,8,FALSE) -> A | AF17: =VLOOKUP($C17,[1]量産!$C$4:$N$15550,9,FALSE) -> 0 | AG17: =VLOOKUP($C17,[1]量産!$C$4:$N$15550,10,FALSE) -> 0 | AH17: =VLOOKUP($C17,[1]量産!$C$4:$N$15550,11,FALSE) -> 0 | AI17: =VLOOKUP($C17,[1]量産!$C$4:$N$15550,12,FALSE) -> 0 | AL17: =C17 -> 7552127213 | AM17: =B17 | AN17: =E17 -> I4K6681VK00 B-GR アース位置の不具合設変 | AP17: 8975246721 | AQ17: =VLOOKUP(AP17,AL17:AM874,2,FALSE) -> C | AR17: =VLOOKUP(AP17,AL17:AN874,3,FALSE) -> 久しぶり | BK17: =VLOOKUP(C:C,[2]Sheet2!$A:$A,1,FALSE) -> #N/A
A18: 37 | C18: 8977943463 | D18: VK04 NMS | E18: I4K6850VK04 A1-GR 1生向け設変出図 | F18: 1 | H18: 初 | L18: 1 | M18: 2 | N18: 2 | O18: 2 | P18: 1 | Q18: 1 | R18: 1 | T18: 1 | V18: 11 | W18: FRAME ASM | X18: VK04 | Y18: =VLOOKUP($C18,[1]量産!$C$4:$N$15550,2,FALSE) -> I4K5796 | Z18: =VLOOKUP($C18,[1]量産!$C$4:$N$15550,3,FALSE) -> 45770 | AA18: =VLOOKUP($C18,[1]量産!$C$4:$N$15550,4,FALSE) -> VK04 A2-Gr | AB18: =VLOOKUP($C18,[1]量産!$C$4:$N$15550,5,FALSE) -> VK04A2-Gr1SEI | AC18: =VLOOKUP($C18,[1]量産!$C$4:$N$15550,6,FALSE) -> VK04A2-Gr1SEI向け設変出図 | AD18: =VLOOKUP($C18,[1]量産!$C$4:$N$15550,7,FALSE) -> 0 | AE18: =VLOOKUP($C18,[1]量産!$C$4:$N$15550,8,FALSE) -> 0 | AF18: =VLOOKUP($C18,[1]量産!$C$4:$N$15550,9,FALSE) -> 0 | AG18: =VLOOKUP($C18,[1]量産!$C$4:$N$15550,10,FALSE) -> 0 | AH18: =VLOOKUP($C18,[1]量産!$C$4:$N$15550,11,FALSE) -> 0 | AI18: =VLOOKUP($C18,[1]量産!$C$4:$N$15550,12,FALSE) -> 0 | AL18: =C18 -> 8977943463 | AM18: =B18 | AN18: =E18 -> I4K6850VK04 A1-GR 1生向け設変出図 | AP18: 8977917770 | AQ18: =VLOOKUP(AP18,AL18:AM875,2,FALSE) -> C | AR18: =VLOOKUP(AP18,AL18:AN875,3,FALSE) -> VL32 D2-GR 850幅 FRAME ASM SOP 新規出図 | BK18: =VLOOKUP(C:C,[2]Sheet2!$A:$A,1,FALSE) -> #N/A
A19: 38 | C19: 8977944054 | D19: VK04 NMS | E19: VK04 A1-GR 1生向け設変出図 | F19: 1 | H19: 初 | L19: 1 | M19: 2 | N19: 2 | O19: 1 | V19: 6 | W19: FRAME ASM | X19: VK04 | Y19: =VLOOKUP($C19,[1]量産!$C$4:$N$15550,2,FALSE) -> I4K5796 | Z19: =VLOOKUP($C19,[1]量産!$C$4:$N$15550,3,FALSE) -> 45770 | AA19: =VLOOKUP($C19,[1]量産!$C$4:$N$15550,4,FALSE) -> VK04 A2-Gr | AB19: =VLOOKUP($C19,[1]量産!$C$4:$N$15550,5,FALSE) -> VK04A2-Gr1SEI | AC19: =VLOOKUP($C19,[1]量産!$C$4:$N$15550,6,FALSE) -> VK04A2-Gr1SEI向け設変出図 | AD19: =VLOOKUP($C19,[1]量産!$C$4:$N$15550,7,FALSE) -> 0 | AE19: =VLOOKUP($C19,[1]量産!$C$4:$N$15550,8,FALSE) -> 0 | AF19: =VLOOKUP($C19,[1]量産!$C$4:$N$15550,9,FALSE) -> 0 | AG19: =VLOOKUP($C19,[1]量産!$C$4:$N$15550,10,FALSE) -> 0 | AH19: =VLOOKUP($C19,[1]量産!$C$4:$N$15550,11,FALSE) -> 0 | AI19: =VLOOKUP($C19,[1]量産!$C$4:$N$15550,12,FALSE) -> 0 | AL19: =C19 -> 8977944054 | AM19: =B19 | AN19: =E19 -> VK04 A1-GR 1生向け設変出図 | AP19: 8983991350 | AQ19: =VLOOKUP(AP19,AL19:AM876,2,FALSE) -> C | AR19: =VLOOKUP(AP19,AL19:AN876,3,FALSE) -> 久しぶり | BK19: =VLOOKUP(C:C,[2]Sheet2!$A:$A,1,FALSE) -> #N/A
A20: 16 | C20: 7552208252 | D20: VK04 NKR | E20: I4K5796VK04 A2-GR 1生向け設変出図 | F20: 1 | H20: 初 | M20: 1 | N20: 5 | O20: 3 | P20: 5 | Q20: 5 | R20: 5 | S20: 5 | T20: 9 | U20: 7 | V20: 45 | W20: FRAME ASM | X20: VK04 | Y20: =VLOOKUP($C20,[1]量産!$C$4:$N$15550,2,FALSE) -> I4K5796 | Z20: =VLOOKUP($C20,[1]量産!$C$4:$N$15550,3,FALSE) -> 45770 | AA20: =VLOOKUP($C20,[1]量産!$C$4:$N$15550,4,FALSE) -> VK04 A2-Gr | AB20: =VLOOKUP($C20,[1]量産!$C$4:$N$15550,5,FALSE) -> VK04A2-Gr1SEI | AC20: =VLOOKUP($C20,[1]量産!$C$4:$N$15550,6,FALSE) -> VK04A2-Gr1SEI向け設変出図 | AD20: =VLOOKUP($C20,[1]量産!$C$4:$N$15550,7,FALSE) -> 0 | AE20: =VLOOKUP($C20,[1]量産!$C$4:$N$15550,8,FALSE) -> D | AF20: =VLOOKUP($C20,[1]量産!$C$4:$N$15550,9,FALSE) -> 0 | AG20: =VLOOKUP($C20,[1]量産!$C$4:$N$15550,10,FALSE) -> 0 | AH20: =VLOOKUP($C20,[1]量産!$C$4:$N$15550,11,FALSE) -> 0 | AI20: =VLOOKUP($C20,[1]量産!$C$4:$N$15550,12,FALSE) -> 0 | AL20: =C20 -> 7552208252 | AM20: =B20 | AN20: =E20 -> I4K5796VK04 A2-GR 1生向け設変出図 | AP20: 7552418121 | AQ20: =VLOOKUP(AP20,AL20:AM877,2,FALSE) -> C | AR20: =VLOOKUP(AP20,AL20:AN877,3,FALSE) -> VK00 3X 850幅 B1-GR FRAME ASM 設変出図(内容：FRAME ASM内容品最新化,S/M ASM LH 溶接NUT及びSTIFF SUB SPG BRKT追加,RIVET削除,REINF LH 溶接NUT追加) | BK20: =VLOOKUP(C:C,[2]Sheet2!$A:$A,1,FALSE) -> #N/A
A21: 22 | C21: 7552224911 | D21: VK04 NMR | E21: VK04 A2-GR 1生向け設変出図 | F21: 1 | H21: 初 | M21: 1 | N21: 5 | O21: 4 | P21: 3 | Q21: 2 | R21: 2 | S21: 3 | T21: 9 | U21: 5 | V21: 34 | W21: FRAME ASM | X21: VK04 | Y21: =VLOOKUP($C21,[1]量産!$C$4:$N$15550,2,FALSE) -> I4K5796 | Z21: =VLOOKUP($C21,[1]量産!$C$4:$N$15550,3,FALSE) -> 45770 | AA21: =VLOOKUP($C21,[1]量産!$C$4:$N$15550,4,FALSE) -> VK04 A2-Gr | AB21: =VLOOKUP($C21,[1]量産!$C$4:$N$15550,5,FALSE) -> VK04A2-Gr1SEI | AC21: =VLOOKUP($C21,[1]量産!$C$4:$N$15550,6,FALSE) -> VK04A2-Gr1SEI向け設変出図 | AD21: =VLOOKUP($C21,[1]量産!$C$4:$N$15550,7,FALSE) -> 0 | AE21: =VLOOKUP($C21,[1]量産!$C$4:$N$15550,8,FALSE) -> A | AF21: =VLOOKUP($C21,[1]量産!$C$4:$N$15550,9,FALSE) -> 0 | AG21: =VLOOKUP($C21,[1]量産!$C$4:$N$15550,10,FALSE) -> 0 | AH21: =VLOOKUP($C21,[1]量産!$C$4:$N$15550,11,FALSE) -> 0 | AI21: =VLOOKUP($C21,[1]量産!$C$4:$N$15550,12,FALSE) -> 0 | AL21: =C21 -> 7552224911 | AM21: =B21 | AN21: =E21 -> VK04 A2-GR 1生向け設変出図 | AP21: 8976682130 | AQ21: =VLOOKUP(AP21,AL6:AM845,2,FALSE) -> A | AR21: =VLOOKUP(AP21,AL6:AN845,3,FALSE) -> 久しぶり | BK21: =VLOOKUP(C:C,[2]Sheet2!$A:$A,1,FALSE) -> #N/A
A22: 26 | C22: 7552264421 | D22: VK04 NPR | E22: VK04 A2-GR SOP向け設変出図 | F22: 1 | H22: 初 | M22: 2 | N22: 5 | O22: 4 | P22: 2 | Q22: 2 | R22: 2 | S22: 4 | T22: 11 | U22: 8 | V22: 40 | W22: FRAME ASM | X22: VK04 | Y22: =VLOOKUP($C22,[1]量産!$C$4:$N$15550,2,FALSE) -> I4K5703 | Z22: =VLOOKUP($C22,[1]量産!$C$4:$N$15550,3,FALSE) -> 45869 | AA22: =VLOOKUP($C22,[1]量産!$C$4:$N$15550,4,FALSE) -> VK04 NPR | AB22: =VLOOKUP($C22,[1]量産!$C$4:$N$15550,5,FALSE) -> VK04 A2-Gr SOP | AC22: =VLOOKUP($C22,[1]量産!$C$4:$N$15550,6,FALSE) -> VK04 A2-Gr SOP向け設変出図 | AD22: =VLOOKUP($C22,[1]量産!$C$4:$N$15550,7,FALSE) -> 0 | AE22: =VLOOKUP($C22,[1]量産!$C$4:$N$15550,8,FALSE) -> 0 | AF22: =VLOOKUP($C22,[1]量産!$C$4:$N$15550,9,FALSE) -> 0 | AG22: =VLOOKUP($C22,[1]量産!$C$4:$N$15550,10,FALSE) -> 0 | AH22: =VLOOKUP($C22,[1]量産!$C$4:$N$15550,11,FALSE) -> 0 | AI22: =VLOOKUP($C22,[1]量産!$C$4:$N$15550,12,FALSE) -> 0 | AL22: =C22 -> 7552264421 | AM22: =B22 | AN22: =E22 -> VK04 A2-GR SOP向け設変出図 | AP22: 8978767114 | AQ22: =VLOOKUP(AP22,AL22:AM857,2,FALSE) -> #N/A | AR22: =VLOOKUP(AP22,AL22:AN857,3,FALSE) -> #N/A | BK22: =VLOOKUP(C:C,[2]Sheet2!$A:$A,1,FALSE) -> #N/A
A23: 27 | C23: 7552264441 | D23: VK04 NPR | E23: VK04 A2-GR SOP向け設変出図 | F23: 1 | H23: 初 | M23: 1 | N23: 3 | O23: 3 | P23: 1 | Q23: 1 | R23: 1 | S23: 2 | T23: 9 | U23: 6 | V23: 27 | W23: FRAME ASM | X23: VK04 | Y23: =VLOOKUP($C23,[1]量産!$C$4:$N$15550,2,FALSE) -> I4K5703 | Z23: =VLOOKUP($C23,[1]量産!$C$4:$N$15550,3,FALSE) -> 45869 | AA23: =VLOOKUP($C23,[1]量産!$C$4:$N$15550,4,FALSE) -> VK04 NPR | AB23: =VLOOKUP($C23,[1]量産!$C$4:$N$15550,5,FALSE) -> VK04 A2-Gr SOP | AC23: =VLOOKUP($C23,[1]量産!$C$4:$N$15550,6,FALSE) -> VK04 A2-Gr SOP向け設変出図 | AD23: =VLOOKUP($C23,[1]量産!$C$4:$N$15550,7,FALSE) -> 0 | AE23: =VLOOKUP($C23,[1]量産!$C$4:$N$15550,8,FALSE) -> 0 | AF23: =VLOOKUP($C23,[1]量産!$C$4:$N$15550,9,FALSE) -> 0 | AG23: =VLOOKUP($C23,[1]量産!$C$4:$N$15550,10,FALSE) -> 0 | AH23: =VLOOKUP($C23,[1]量産!$C$4:$N$15550,11,FALSE) -> 0 | AI23: =VLOOKUP($C23,[1]量産!$C$4:$N$15550,12,FALSE) -> 0 | AL23: =C23 -> 7552264441 | AM23: =B23 | AN23: =E23 -> VK04 A2-GR SOP向け設変出図 | AP23: 8972416603 | AQ23: =VLOOKUP(AP23,AL23:AM858,2,FALSE) -> #N/A | AR23: =VLOOKUP(AP23,AL23:AN858,3,FALSE) -> #N/A | BK23: =VLOOKUP(C:C,[2]Sheet2!$A:$A,1,FALSE) -> #N/A
A24: 30 | C24: 7552646521 | D24: VK04 NPR | E24: VK04 A2-GR SOP向け設変出図 | F24: 1 | H24: 初 | M24: 1 | O24: 1 | P24: 1 | Q24: 1 | R24: 1 | S24: 1 | T24: 4 | U24: 2 | V24: 12 | W24: FRAME ASM | X24: VK04 | Y24: =VLOOKUP($C24,[1]量産!$C$4:$N$15550,2,FALSE) -> I4K5703 | Z24: =VLOOKUP($C24,[1]量産!$C$4:$N$15550,3,FALSE) -> 45869 | AA24: =VLOOKUP($C24,[1]量産!$C$4:$N$15550,4,FALSE) -> VK04 NPR | AB24: =VLOOKUP($C24,[1]量産!$C$4:$N$15550,5,FALSE) -> VK04 A2-Gr SOP | AC24: =VLOOKUP($C24,[1]量産!$C$4:$N$15550,6,FALSE) -> VK04 A2-Gr SOP向け設変出図 | AD24: =VLOOKUP($C24,[1]量産!$C$4:$N$15550,7,FALSE) -> 0 | AE24: =VLOOKUP($C24,[1]量産!$C$4:$N$15550,8,FALSE) -> 0 | AF24: =VLOOKUP($C24,[1]量産!$C$4:$N$15550,9,FALSE) -> 0 | AG24: =VLOOKUP($C24,[1]量産!$C$4:$N$15550,10,FALSE) -> 0 | AH24: =VLOOKUP($C24,[1]量産!$C$4:$N$15550,11,FALSE) -> 0 | AI24: =VLOOKUP($C24,[1]量産!$C$4:$N$15550,12,FALSE) -> 0 | AL24: =C24 -> 7552646521 | AM24: =B24 | AN24: =E24 -> VK04 A2-GR SOP向け設変出図 | AP24: 8983826061 | AQ24: =VLOOKUP(AP24,AL24:AM878,2,FALSE) -> C | AR24: =VLOOKUP(AP24,AL24:AN878,3,FALSE) -> #N/A | BK24: =VLOOKUP(C:C,[2]Sheet2!$A:$A,1,FALSE) -> #N/A
A25: 32 | C25: 7552693441 | D25: VK04 NPR | E25: VK04 A2-GR SOP向け設変出図 | F25: 1 | H25: 初 | M25: 1 | N25: 2 | S25: 1 | T25: 4 | U25: 3 | V25: 11 | W25: FRAME ASM | X25: VK04 | Y25: =VLOOKUP($C25,[1]量産!$C$4:$N$15550,2,FALSE) -> I4K5703 | Z25: =VLOOKUP($C25,[1]量産!$C$4:$N$15550,3,FALSE) -> 45869 | AA25: =VLOOKUP($C25,[1]量産!$C$4:$N$15550,4,FALSE) -> VK04 NPR | AB25: =VLOOKUP($C25,[1]量産!$C$4:$N$15550,5,FALSE) -> VK04 A2-Gr SOP | AC25: =VLOOKUP($C25,[1]量産!$C$4:$N$15550,6,FALSE) -> VK04 A2-Gr SOP向け設変出図 | AD25: =VLOOKUP($C25,[1]量産!$C$4:$N$15550,7,FALSE) -> 0 | AE25: =VLOOKUP($C25,[1]量産!$C$4:$N$15550,8,FALSE) -> 0 | AF25: =VLOOKUP($C25,[1]量産!$C$4:$N$15550,9,FALSE) -> 0 | AG25: =VLOOKUP($C25,[1]量産!$C$4:$N$15550,10,FALSE) -> 0 | AH25: =VLOOKUP($C25,[1]量産!$C$4:$N$15550,11,FALSE) -> 0 | AI25: =VLOOKUP($C25,[1]量産!$C$4:$N$15550,12,FALSE) -> 0 | AL25: =C25 -> 7552693441 | AM25: =B25 | AN25: =E25 -> VK04 A2-GR SOP向け設変出図 | AP25: 7551909131 | AQ25: =VLOOKUP(AP25,AL25:AM879,2,FALSE) -> A | AR25: =VLOOKUP(AP25,AL25:AN879,3,FALSE) -> 久しぶり | BK25: =VLOOKUP(C:C,[2]Sheet2!$A:$A,1,FALSE) -> #N/A
A26: 17 | C26: 7552208652 | D26: VK04 NKR | E26: I4K7240VK04 A2-GR 向け K/UP DUMP FRAME変更設変 | F26: 1 | H26: 初 | M26: 1 | N26: 1 | O26: 1 | P26: 4 | Q26: 3 | R26: 3 | S26: 4 | T26: 10 | U26: 7 | V26: 34 | W26: FRAME ASM | X26: VK04 | Y26: =VLOOKUP($C26,[1]量産!$C$4:$N$15550,2,FALSE) -> I4K7240 | Z26: =VLOOKUP($C26,[1]量産!$C$4:$N$15550,3,FALSE) -> 45888 | AA26: =VLOOKUP($C26,[1]量産!$C$4:$N$15550,4,FALSE) -> VK04 A2-Gr | AB26: =VLOOKUP($C26,[1]量産!$C$4:$N$15550,5,FALSE) -> VK04A2-Gr | AC26: =VLOOKUP($C26,[1]量産!$C$4:$N$15550,6,FALSE) -> VK04 A2-Gr 向け K/UP DUMP FRAME 変更設変 | AD26: =VLOOKUP($C26,[1]量産!$C$4:$N$15550,7,FALSE) -> 0 | AE26: =VLOOKUP($C26,[1]量産!$C$4:$N$15550,8,FALSE) -> D | AF26: =VLOOKUP($C26,[1]量産!$C$4:$N$15550,9,FALSE) -> 0 | AG26: =VLOOKUP($C26,[1]量産!$C$4:$N$15550,10,FALSE) -> 0 | AH26: =VLOOKUP($C26,[1]量産!$C$4:$N$15550,11,FALSE) -> 0 | AI26: =VLOOKUP($C26,[1]量産!$C$4:$N$15550,12,FALSE) -> 0 | AL26: =C26 -> 7552208652 | AM26: =B26 | AN26: =E26 -> I4K7240VK04 A2-GR 向け K/UP DUMP FRAME変更設変 | AP26: 8977943117 | AQ26: =VLOOKUP(AP26,AL26:AM880,2,FALSE) -> K | AR26: =VLOOKUP(AP26,AL26:AN880,3,FALSE) -> VK04 A1-GR SOP向け設変出図 | BK26: =VLOOKUP(C:C,[2]Sheet2!$A:$A,1,FALSE) -> #N/A
A27: 33 | C27: 7552715130 | D27: NMR | E27: I3K5492VK05 A-GR 欧州/トルコ/UK向け 新規出図 | F27: 1 | H27: 初 | O27: 1 | V27: 1 | W27: FRAME ASM | X27: NMR | Y27: =VLOOKUP($C27,[1]量産!$C$4:$N$15550,2,FALSE) -> I3K5492 | Z27: =VLOOKUP($C27,[1]量産!$C$4:$N$15550,3,FALSE) -> 45726 | AA27: =VLOOKUP($C27,[1]量産!$C$4:$N$15550,4,FALSE) -> VK05 A-Gr | AB27: =VLOOKUP($C27,[1]量産!$C$4:$N$15550,5,FALSE) -> VK05A-Gr | AC27: =VLOOKUP($C27,[1]量産!$C$4:$N$15550,6,FALSE) -> VK05 A-Gr 欧州/トルコ/UK向け 新規出図 | AD27: =VLOOKUP($C27,[1]量産!$C$4:$N$15550,7,FALSE) -> 0 | AE27: =VLOOKUP($C27,[1]量産!$C$4:$N$15550,8,FALSE) -> 0 | AF27: =VLOOKUP($C27,[1]量産!$C$4:$N$15550,9,FALSE) -> 0 | AG27: =VLOOKUP($C27,[1]量産!$C$4:$N$15550,10,FALSE) -> 未 | AH27: =VLOOKUP($C27,[1]量産!$C$4:$N$15550,11,FALSE) -> 未 | AI27: =VLOOKUP($C27,[1]量産!$C$4:$N$15550,12,FALSE) -> 未 | AL27: =C27 -> 7552715130 | AM27: =B27 | AN27: =E27 -> I3K5492VK05 A-GR 欧州/トルコ/UK向け 新規出図 | AP27: 8978767523 | AQ27: =VLOOKUP(AP27,AL27:AM881,2,FALSE) -> A | AR27: =VLOOKUP(AP27,AL27:AN881,3,FALSE) -> VK04 A1-GR 1生向け設変出図 | BK27: =VLOOKUP(C:C,[2]Sheet2!$A:$A,1,FALSE) -> 7552715130
A28: 34 | C28: 7552765870 | D28: VK05 NPR | E28: I3K5639VK05 B-GR K研向け新規出図 | F28: 1 | H28: 初 | O28: 1 | V28: 1 | W28: FRAME ASM | X28: VK05 | Y28: =VLOOKUP($C28,[1]量産!$C$4:$N$15550,2,FALSE) -> I3K5639 | Z28: =VLOOKUP($C28,[1]量産!$C$4:$N$15550,3,FALSE) -> 45813 | AA28: =VLOOKUP($C28,[1]量産!$C$4:$N$15550,4,FALSE) -> VK05 B-Gr | AB28: =VLOOKUP($C28,[1]量産!$C$4:$N$15550,5,FALSE) -> VK05 B-Gr KKEN | AC28: =VLOOKUP($C28,[1]量産!$C$4:$N$15550,6,FALSE) -> VK05 B-Gr KKEN 新規出図 | AD28: =VLOOKUP($C28,[1]量産!$C$4:$N$15550,7,FALSE) -> 0 | AE28: =VLOOKUP($C28,[1]量産!$C$4:$N$15550,8,FALSE) -> 0 | AF28: =VLOOKUP($C28,[1]量産!$C$4:$N$15550,9,FALSE) -> 0 | AG28: =VLOOKUP($C28,[1]量産!$C$4:$N$15550,10,FALSE) -> 0 | AH28: =VLOOKUP($C28,[1]量産!$C$4:$N$15550,11,FALSE) -> 0 | AI28: =VLOOKUP($C28,[1]量産!$C$4:$N$15550,12,FALSE) -> 0 | AL28: =C28 -> 7552765870 | AM28: =B28 | AN28: =E28 -> I3K5639VK05 B-GR K研向け新規出図 | AP28: 7552418121 | AQ28: =VLOOKUP(AP28,AL28:AM882,2,FALSE) -> C | AR28: =VLOOKUP(AP28,AL28:AN882,3,FALSE) -> VK00 3X 850幅 B1-GR FRAME ASM 設変出図(内容：FRAME ASM内容品最新化,S/M ASM LH 溶接NUT及びSTIFF SUB SPG BRKT追加,RIVET削除,REINF LH 溶接NUT追加) | BK28: =VLOOKUP(C:C,[2]Sheet2!$A:$A,1,FALSE) -> 7552765870
A29: 24 | C29: 7552225481 | D29: VK04 NMR | E29: I4K5796VK04 A2-GR 1生向け設変出図 | F29: 1 | H29: 初 | O29: 1 | P29: 1 | Q29: 1 | S29: 1 | T29: 2 | U29: 1 | V29: 7 | W29: FRAME ASM | X29: VK04 | Y29: =VLOOKUP($C29,[1]量産!$C$4:$N$15550,2,FALSE) -> I4K5796 | Z29: =VLOOKUP($C29,[1]量産!$C$4:$N$15550,3,FALSE) -> 45770 | AA29: =VLOOKUP($C29,[1]量産!$C$4:$N$15550,4,FALSE) -> VK04 A2-Gr | AB29: =VLOOKUP($C29,[1]量産!$C$4:$N$15550,5,FALSE) -> VK04A2-Gr1SEI | AC29: =VLOOKUP($C29,[1]量産!$C$4:$N$15550,6,FALSE) -> VK04A2-Gr1SEI向け設変出図 | AD29: =VLOOKUP($C29,[1]量産!$C$4:$N$15550,7,FALSE) -> 0 | AE29: =VLOOKUP($C29,[1]量産!$C$4:$N$15550,8,FALSE) -> A | AF29: =VLOOKUP($C29,[1]量産!$C$4:$N$15550,9,FALSE) -> 0 | AG29: =VLOOKUP($C29,[1]量産!$C$4:$N$15550,10,FALSE) -> 0 | AH29: =VLOOKUP($C29,[1]量産!$C$4:$N$15550,11,FALSE) -> 0 | AI29: =VLOOKUP($C29,[1]量産!$C$4:$N$15550,12,FALSE) -> 0 | AL29: =C29 -> 7552225481 | AM29: =B29 | AN29: =E29 -> I4K5796VK04 A2-GR 1生向け設変出図 | AP29: 7552222861 | AQ29: =VLOOKUP(AP29,AL29:AM883,2,FALSE) -> A | AR29: =VLOOKUP(AP29,AL29:AN883,3,FALSE) -> VK00 B2-GR 一生向け 700幅 設変出図(内容:構成部品の最新化、溶接NUT変更) | BK29: =VLOOKUP(C:C,[2]Sheet2!$A:$A,1,FALSE) -> #N/A
A30: 25 | C30: 7552225491 | D30: VK04 NMR | E30: I4K5796VK04 A2-GR 1生向け設変出図 | F30: 1 | H30: 初 | O30: 1 | P30: 1 | Q30: 1 | R30: 1 | S30: 1 | T30: 3 | U30: 2 | V30: 10 | W30: FRAME ASM | X30: VK04 | Y30: =VLOOKUP($C30,[1]量産!$C$4:$N$15550,2,FALSE) -> I4K5796 | Z30: =VLOOKUP($C30,[1]量産!$C$4:$N$15550,3,FALSE) -> 45770 | AA30: =VLOOKUP($C30,[1]量産!$C$4:$N$15550,4,FALSE) -> VK04 A2-Gr | AB30: =VLOOKUP($C30,[1]量産!$C$4:$N$15550,5,FALSE) -> VK04A2-Gr1SEI | AC30: =VLOOKUP($C30,[1]量産!$C$4:$N$15550,6,FALSE) -> VK04A2-Gr1SEI向け設変出図 | AD30: =VLOOKUP($C30,[1]量産!$C$4:$N$15550,7,FALSE) -> 0 | AE30: =VLOOKUP($C30,[1]量産!$C$4:$N$15550,8,FALSE) -> A | AF30: =VLOOKUP($C30,[1]量産!$C$4:$N$15550,9,FALSE) -> 0 | AG30: =VLOOKUP($C30,[1]量産!$C$4:$N$15550,10,FALSE) -> 0 | AH30: =VLOOKUP($C30,[1]量産!$C$4:$N$15550,11,FALSE) -> 0 | AI30: =VLOOKUP($C30,[1]量産!$C$4:$N$15550,12,FALSE) -> 0 | AL30: =C30 -> 7552225491 | AM30: =B30 | AN30: =E30 -> I4K5796VK04 A2-GR 1生向け設変出図 | AP30: 7552222871 | AQ30: =VLOOKUP(AP30,AL30:AM884,2,FALSE) -> A | AR30: =VLOOKUP(AP30,AL30:AN884,3,FALSE) -> VK00 B2-GR 一生向け 700幅 設変出図(内容:構成部品の最新化、溶接NUT変更) | BK30: =VLOOKUP(C:C,[2]Sheet2!$A:$A,1,FALSE) -> #N/A
A31: 23 | C31: 7552224951 | D31: VK04 NKR | E31: VK04 A2-GR 1生向け設変出図 | F31: 1 | H31: 初 | O31: 1 | P31: 1 | Q31: 1 | S31: 1 | T31: 1 | V31: 5 | W31: FRAME ASM | X31: VK04 | Y31: =VLOOKUP($C31,[1]量産!$C$4:$N$15550,2,FALSE) -> I4K5796 | Z31: =VLOOKUP($C31,[1]量産!$C$4:$N$15550,3,FALSE) -> 45770 | AA31: =VLOOKUP($C31,[1]量産!$C$4:$N$15550,4,FALSE) -> VK04 A2-Gr | AB31: =VLOOKUP($C31,[1]量産!$C$4:$N$15550,5,FALSE) -> VK04A2-Gr1SEI | AC31: =VLOOKUP($C31,[1]量産!$C$4:$N$15550,6,FALSE) -> VK04A2-Gr1SEI向け設変出図 | AD31: =VLOOKUP($C31,[1]量産!$C$4:$N$15550,7,FALSE) -> 0 | AE31: =VLOOKUP($C31,[1]量産!$C$4:$N$15550,8,FALSE) -> 0 | AF31: =VLOOKUP($C31,[1]量産!$C$4:$N$15550,9,FALSE) -> 0 | AG31: =VLOOKUP($C31,[1]量産!$C$4:$N$15550,10,FALSE) -> 0 | AH31: =VLOOKUP($C31,[1]量産!$C$4:$N$15550,11,FALSE) -> 0 | AI31: =VLOOKUP($C31,[1]量産!$C$4:$N$15550,12,FALSE) -> 0 | AL31: =C31 -> 7552224951 | AM31: =B31 | AN31: =E31 -> VK04 A2-GR 1生向け設変出図 | AP31: 7552312630 | AQ31: =VLOOKUP(AP31,AL31:AM885,2,FALSE) -> A | AR31: =VLOOKUP(AP31,AL31:AN885,3,FALSE) -> VK02 A-GR K研 FRAME ASM 新規出図 | BK31: =VLOOKUP(C:C,[2]Sheet2!$A:$A,1,FALSE) -> #N/A
A32: 3 | C32: 7551946401 | D32: VK00 NMR | E32: I4K4402VK00 B1-GR 一生向け FRAME ASM 設変出図(内容:穴・NUT変更、構成部品変更及び更新) | F32: 1 | H32: 初 | O32: 1 | P32: 1 | Q32: 1 | R32: 1 | S32: 1 | T32: 1 | V32: 6 | W32: FRAME ASM | X32: VK00 | Y32: =VLOOKUP($C32,[1]量産!$C$4:$N$15550,2,FALSE) -> I4K4402 | Z32: =VLOOKUP($C32,[1]量産!$C$4:$N$15550,3,FALSE) -> 45391 | AA32: =VLOOKUP($C32,[1]量産!$C$4:$N$15550,4,FALSE) -> VK00 NMR | AB32: =VLOOKUP($C32,[1]量産!$C$4:$N$15550,5,FALSE) -> VK00 B1-Gr | AC32: =VLOOKUP($C32,[1]量産!$C$4:$N$15550,6,FALSE) -> VK00 B1-GR 一生向け FRAME ASM 設変出図(内容:穴・NUT変更、構成部品変更及び更新) | AD32: =VLOOKUP($C32,[1]量産!$C$4:$N$15550,7,FALSE) -> 0 | AE32: =VLOOKUP($C32,[1]量産!$C$4:$N$15550,8,FALSE) -> A | AF32: =VLOOKUP($C32,[1]量産!$C$4:$N$15550,9,FALSE) -> 0 | AG32: =VLOOKUP($C32,[1]量産!$C$4:$N$15550,10,FALSE) -> 未 | AH32: =VLOOKUP($C32,[1]量産!$C$4:$N$15550,11,FALSE) -> 未 | AI32: =VLOOKUP($C32,[1]量産!$C$4:$N$15550,12,FALSE) -> 未 | AL32: =C32 -> 7551946401 | AM32: =B32 | AN32: =E32 -> I4K4402VK00 B1-GR 一生向け FRAME ASM 設変出図(内容:穴・NUT変更、構成部品変更及び更新) | AP32: 8978363795 | AQ32: =VLOOKUP(AP32,AL32:AM886,2,FALSE) -> A | AR32: =VLOOKUP(AP32,AL32:AN886,3,FALSE) -> VK04 A1-GR 1生向け設変出図 | BK32: =VLOOKUP(C:C,[2]Sheet2!$A:$A,1,FALSE) -> #N/A
A33: 4 | C33: 7551946411 | D33: VK00 NMR | E33: VK00 B1-GR 一生向け FRAME ASM 設変出図(内容:穴・NUT変更、構成部品変更及び更新) | F33: 1 | H33: 初 | O33: 1 | P33: 1 | Q33: 1 | R33: 1 | S33: 1 | T33: 1 | V33: 6 | W33: FRAME ASM | X33: VK00 | Y33: =VLOOKUP($C33,[1]量産!$C$4:$N$15550,2,FALSE) -> I4K4402 | Z33: =VLOOKUP($C33,[1]量産!$C$4:$N$15550,3,FALSE) -> 45391 | AA33: =VLOOKUP($C33,[1]量産!$C$4:$N$15550,4,FALSE) -> VK00 NMR | AB33: =VLOOKUP($C33,[1]量産!$C$4:$N$15550,5,FALSE) -> VK00 B1-Gr | AC33: =VLOOKUP($C33,[1]量産!$C$4:$N$15550,6,FALSE) -> VK00 B1-GR 一生向け FRAME ASM 設変出図(内容:穴・NUT変更、構成部品変更及び更新) | AD33: =VLOOKUP($C33,[1]量産!$C$4:$N$15550,7,FALSE) -> 0 | AE33: =VLOOKUP($C33,[1]量産!$C$4:$N$15550,8,FALSE) -> A | AF33: =VLOOKUP($C33,[1]量産!$C$4:$N$15550,9,FALSE) -> 0 | AG33: =VLOOKUP($C33,[1]量産!$C$4:$N$15550,10,FALSE) -> 未 | AH33: =VLOOKUP($C33,[1]量産!$C$4:$N$15550,11,FALSE) -> 未 | AI33: =VLOOKUP($C33,[1]量産!$C$4:$N$15550,12,FALSE) -> 未 | AL33: =C33 -> 7551946411 | AM33: =B33 | AN33: =E33 -> VK00 B1-GR 一生向け FRAME ASM 設変出図(内容:穴・NUT変更、構成部品変更及び更新) | AP33: 7551885852 | AQ33: =VLOOKUP(AP33,AL33:AM887,2,FALSE) -> A | AR33: =VLOOKUP(AP33,AL33:AN887,3,FALSE) -> 久しぶり | BK33: =VLOOKUP(C:C,[2]Sheet2!$A:$A,1,FALSE) -> #N/A
A34: 13 | C34: 7552165001 | D34: VK00 NP* | E34: I4K4072VK00 B1-GR 850幅 一生向け FRAME ASM 設変出図(内容:溶接NUT変更,W/PAINT部品 表面処理の変更,K研でのECR内容を今後のイベントに反映) | F34: 1 | H34: 初 | O34: 1 | P34: 1 | Q34: 1 | V34: 3 | W34: FRAME ASM | X34: VK00 | Y34: =VLOOKUP($C34,[1]量産!$C$4:$N$15550,2,FALSE) -> I4K4072 | Z34: =VLOOKUP($C34,[1]量産!$C$4:$N$15550,3,FALSE) -> 45439 | AA34: =VLOOKUP($C34,[1]量産!$C$4:$N$15550,4,FALSE) -> VK00 NP* | AB34: =VLOOKUP($C34,[1]量産!$C$4:$N$15550,5,FALSE) -> VK00 B1-Gr 850幅 | AC34: =VLOOKUP($C34,[1]量産!$C$4:$N$15550,6,FALSE) -> VK00 B1-GR 850幅 一生向け FRAME ASM 設変出図(内容:溶接NUT変更,W/PAINT部品 表面処理の変更,K研でのECR内容を今後のイベントに反映) | AD34: =VLOOKUP($C34,[1]量産!$C$4:$N$15550,7,FALSE) -> 0 | AE34: =VLOOKUP($C34,[1]量産!$C$4:$N$15550,8,FALSE) -> C | AF34: =VLOOKUP($C34,[1]量産!$C$4:$N$15550,9,FALSE) -> 0 | AG34: =VLOOKUP($C34,[1]量産!$C$4:$N$15550,10,FALSE) -> 未 | AH34: =VLOOKUP($C34,[1]量産!$C$4:$N$15550,11,FALSE) -> - | AI34: =VLOOKUP($C34,[1]量産!$C$4:$N$15550,12,FALSE) -> 未 | AL34: =C34 -> 7552165001 | AM34: =B34 | AN34: =E34 -> I4K4072VK00 B1-GR 850幅 一生向け FRAME ASM 設変出図(内容:溶接NUT変更,W/PAINT部品 表面処理の変更,K研でのECR内容を今後のイベントに反映) | AP34: 7551909072 | AQ34: =VLOOKUP(AP34,AL34:AM888,2,FALSE) -> #N/A | AR34: =VLOOKUP(AP34,AL34:AN888,3,FALSE) -> #N/A | BK34: =VLOOKUP(C:C,[2]Sheet2!$A:$A,1,FALSE) -> #N/A
A35: 14 | C35: 7552165512 | D35: VK00 N** | E35: I4K5443VK00 3X 850幅 B1-GR FRAME ASM 設変出図(内容：FRAME ASM内容品最新化,S/M ASM LH 溶接NUT及びSTIFF SUB SPG BRKT追加,RIVET削除,REINF LH 溶接NUT追加) | F35: 1 | H35: 初 | O35: 1 | P35: 1 | Q35: 1 | V35: 3 | W35: FRAME ASM | X35: VK00 | Y35: =VLOOKUP($C35,[1]量産!$C$4:$N$15550,2,FALSE) -> I4K5443 | Z35: =VLOOKUP($C35,[1]量産!$C$4:$N$15550,3,FALSE) -> 45527 | AA35: =VLOOKUP($C35,[1]量産!$C$4:$N$15550,4,FALSE) -> VK00 N** | AB35: =VLOOKUP($C35,[1]量産!$C$4:$N$15550,5,FALSE) -> VK00 B1-Gr 850幅 | AC35: =VLOOKUP($C35,[1]量産!$C$4:$N$15550,6,FALSE) -> VK00 3X 850幅 B1-GR FRAME ASM 設変出図(内容：FRAME ASM内容品最新化,S/M ASM LH 溶接NUT及びSTIFF SUB SPG BRKT追加,RIVET削除,REINF LH 溶接NUT追加) | AD35: =VLOOKUP($C35,[1]量産!$C$4:$N$15550,7,FALSE) -> 0 | AE35: =VLOOKUP($C35,[1]量産!$C$4:$N$15550,8,FALSE) -> 0 | AF35: =VLOOKUP($C35,[1]量産!$C$4:$N$15550,9,FALSE) -> 0 | AG35: =VLOOKUP($C35,[1]量産!$C$4:$N$15550,10,FALSE) -> 未 | AH35: =VLOOKUP($C35,[1]量産!$C$4:$N$15550,11,FALSE) -> 未 | AI35: =VLOOKUP($C35,[1]量産!$C$4:$N$15550,12,FALSE) -> 未 | AL35: =C35 -> 7552165512 | AM35: =B35 | AN35: =E35 -> I4K5443VK00 3X 850幅 B1-GR FRAME ASM 設変出図(内容：FRAME ASM内容品最新化,S/M ASM LH 溶接NUT及びSTIFF SUB SPG BRKT追加,RIVET削除,REINF LH 溶接NUT追加) | AP35: 7551909321 | AQ35: =VLOOKUP(AP35,AL35:AM889,2,FALSE) -> A | AR35: =VLOOKUP(AP35,AL35:AN889,3,FALSE) -> #N/A | BK35: =VLOOKUP(C:C,[2]Sheet2!$A:$A,1,FALSE) -> #N/A
A36: 15 | C36: 7552165982 | D36: VK00 N** | E36: VK00 3X 850幅 B1-GR FRAME ASM 設変出図(内容：FRAME ASM内容品最新化,S/M ASM LH 溶接NUT及びSTIFF SUB SPG BRKT追加,RIVET削除,REINF LH 溶接NUT追加) | F36: 1 | H36: 初 | O36: 1 | P36: 1 | Q36: 1 | V36: 3 | W36: FRAME ASM | X36: VK00 | Y36: =VLOOKUP($C36,[1]量産!$C$4:$N$15550,2,FALSE) -> I4K5443 | Z36: =VLOOKUP($C36,[1]量産!$C$4:$N$15550,3,FALSE) -> 45527 | AA36: =VLOOKUP($C36,[1]量産!$C$4:$N$15550,4,FALSE) -> VK00 N** | AB36: =VLOOKUP($C36,[1]量産!$C$4:$N$15550,5,FALSE) -> VK00 B1-Gr 850幅 | AC36: =VLOOKUP($C36,[1]量産!$C$4:$N$15550,6,FALSE) -> VK00 3X 850幅 B1-GR FRAME ASM 設変出図(内容：FRAME ASM内容品最新化,S/M ASM LH 溶接NUT及びSTIFF SUB SPG BRKT追加,RIVET削除,REINF LH 溶接NUT追加) | AD36: =VLOOKUP($C36,[1]量産!$C$4:$N$15550,7,FALSE) -> 0 | AE36: =VLOOKUP($C36,[1]量産!$C$4:$N$15550,8,FALSE) -> 0 | AF36: =VLOOKUP($C36,[1]量産!$C$4:$N$15550,9,FALSE) -> 0 | AG36: =VLOOKUP($C36,[1]量産!$C$4:$N$15550,10,FALSE) -> 未 | AH36: =VLOOKUP($C36,[1]量産!$C$4:$N$15550,11,FALSE) -> 未 | AI36: =VLOOKUP($C36,[1]量産!$C$4:$N$15550,12,FALSE) -> 未 | AL36: =C36 -> 7552165982 | AM36: =B36 | AN36: =E36 -> VK00 3X 850幅 B1-GR FRAME ASM 設変出図(内容：FRAME ASM内容品最新化,S/M ASM LH 溶接NUT及びSTIFF SUB SPG BRKT追加,RIVET削除,REINF LH 溶接NUT追加) | AQ36: =VLOOKUP(AP36,AL36:AM890,2,FALSE) -> 0 | AR36: =VLOOKUP(AP36,AL36:AN890,3,FALSE) -> 0 | BK36: =VLOOKUP(C:C,[2]Sheet2!$A:$A,1,FALSE) -> #N/A
A37: 21 | C37: 7552222921 | D37: VK00 NKR | E37: I4K5030VK00 B2-GR 一生向け 700幅 設変出図(内容:構成部品の最新化、溶接NUT変更) | F37: 1 | H37: 初 | O37: 1 | P37: 1 | Q37: 1 | R37: 1 | V37: 4 | W37: FRAME ASM | X37: VK00 | Y37: =VLOOKUP($C37,[1]量産!$C$4:$N$15550,2,FALSE) -> I4K5030 | Z37: =VLOOKUP($C37,[1]量産!$C$4:$N$15550,3,FALSE) -> 45450 | AA37: =VLOOKUP($C37,[1]量産!$C$4:$N$15550,4,FALSE) -> VK00 NKR | AB37: =VLOOKUP($C37,[1]量産!$C$4:$N$15550,5,FALSE) -> VK00 B2-Gr 700幅 | AC37: =VLOOKUP($C37,[1]量産!$C$4:$N$15550,6,FALSE) -> VK00 B2-GR 一生向け 700幅 設変出図(内容:構成部品の最新化、溶接NUT変更) | AD37: =VLOOKUP($C37,[1]量産!$C$4:$N$15550,7,FALSE) -> 0 | AE37: =VLOOKUP($C37,[1]量産!$C$4:$N$15550,8,FALSE) -> A | AF37: =VLOOKUP($C37,[1]量産!$C$4:$N$15550,9,FALSE) -> 0 | AG37: =VLOOKUP($C37,[1]量産!$C$4:$N$15550,10,FALSE) -> 未 | AH37: =VLOOKUP($C37,[1]量産!$C$4:$N$15550,11,FALSE) -> 未 | AI37: =VLOOKUP($C37,[1]量産!$C$4:$N$15550,12,FALSE) -> 未 | AL37: =C37 -> 7552222921 | AM37: =B37 | AN37: =E37 -> I4K5030VK00 B2-GR 一生向け 700幅 設変出図(内容:構成部品の最新化、溶接NUT変更) | AQ37: =VLOOKUP(AP37,AL37:AM891,2,FALSE) -> 0 | AR37: =VLOOKUP(AP37,AL37:AN891,3,FALSE) -> 0 | BK37: =VLOOKUP(C:C,[2]Sheet2!$A:$A,1,FALSE) -> #N/A
A38: 29 | C38: 7552378530 | D38: VK00 NMR | E38: I3K4234 | F38: 1 | H38: 初 | O38: 1 | P38: 1 | Q38: 1 | R38: 1 | S38: 1 | T38: 2 | V38: 7 | W38: FRAME ASM | X38: VK00 | Y38: =VLOOKUP($C38,[1]量産!$C$4:$N$15550,2,FALSE) -> I3K4234 | Z38: =VLOOKUP($C38,[1]量産!$C$4:$N$15550,3,FALSE) -> 45373 | AA38: =VLOOKUP($C38,[1]量産!$C$4:$N$15550,4,FALSE) -> VK00 NMR | AB38: =VLOOKUP($C38,[1]量産!$C$4:$N$15550,5,FALSE) -> VK00 700幅 | AC38: =VLOOKUP($C38,[1]量産!$C$4:$N$15550,6,FALSE) -> VK00 B1-GR 一生向け FRAME ASM 新規出図 | AD38: =VLOOKUP($C38,[1]量産!$C$4:$N$15550,7,FALSE) -> 0 | AE38: =VLOOKUP($C38,[1]量産!$C$4:$N$15550,8,FALSE) -> A | AF38: =VLOOKUP($C38,[1]量産!$C$4:$N$15550,9,FALSE) -> 0 | AG38: =VLOOKUP($C38,[1]量産!$C$4:$N$15550,10,FALSE) -> 未 | AH38: =VLOOKUP($C38,[1]量産!$C$4:$N$15550,11,FALSE) -> 未 | AI38: =VLOOKUP($C38,[1]量産!$C$4:$N$15550,12,FALSE) -> 未 | AL38: =C38 -> 7552378530 | AM38: =B38 | AN38: =E38 -> I3K4234 | AP38: 7552296090 | AQ38: =VLOOKUP(AP38,AL38:AM892,2,FALSE) -> #N/A | AR38: =VLOOKUP(AP38,AL38:AN892,3,FALSE) -> #N/A | BK38: =VLOOKUP(C:C,[2]Sheet2!$A:$A,1,FALSE) -> #N/A
A39: 42 | C39: 7552472860 | D39: VK05 NPR | E39: I3K6135 | F39: 3 | H39: 初 | P39: 1 | V39: 1 | W39: FRAME ASM | X39: VK05 | Y39: =VLOOKUP($C39,[1]量産!$C$4:$N$15550,2,FALSE) -> #N/A | Z39: =VLOOKUP($C39,[1]量産!$C$4:$N$15550,3,FALSE) -> #N/A | AA39: =VLOOKUP($C39,[1]量産!$C$4:$N$15550,4,FALSE) -> #N/A | AB39: =VLOOKUP($C39,[1]量産!$C$4:$N$15550,5,FALSE) -> #N/A | AC39: =VLOOKUP($C39,[1]量産!$C$4:$N$15550,6,FALSE) -> #N/A | AD39: =VLOOKUP($C39,[1]量産!$C$4:$N$15550,7,FALSE) -> #N/A | AE39: =VLOOKUP($C39,[1]量産!$C$4:$N$15550,8,FALSE) -> #N/A | AF39: =VLOOKUP($C39,[1]量産!$C$4:$N$15550,9,FALSE) -> #N/A | AG39: =VLOOKUP($C39,[1]量産!$C$4:$N$15550,10,FALSE) -> #N/A | AH39: =VLOOKUP($C39,[1]量産!$C$4:$N$15550,11,FALSE) -> #N/A | AI39: =VLOOKUP($C39,[1]量産!$C$4:$N$15550,12,FALSE) -> #N/A | AL39: =C39 -> 7552472860 | AM39: =B39 | AN39: =E39 -> I3K6135 | AQ39: =VLOOKUP(AP39,AL39:AM893,2,FALSE) -> 0 | AR39: =VLOOKUP(AP39,AL39:AN893,3,FALSE) -> 0 | BK39: =VLOOKUP(C:C,[2]Sheet2!$A:$A,1,FALSE) -> 7552472860
A40: 43 | C40: 7552472980 | D40: VK05 NPR | E40: I3K6135 | F40: 3 | H40: 初 | P40: 1 | V40: 1 | W40: FRAME ASM | X40: VK05 | Y40: =VLOOKUP($C40,[1]量産!$C$4:$N$15550,2,FALSE) -> #N/A | Z40: =VLOOKUP($C40,[1]量産!$C$4:$N$15550,3,FALSE) -> #N/A | AA40: =VLOOKUP($C40,[1]量産!$C$4:$N$15550,4,FALSE) -> #N/A | AB40: =VLOOKUP($C40,[1]量産!$C$4:$N$15550,5,FALSE) -> #N/A | AC40: =VLOOKUP($C40,[1]量産!$C$4:$N$15550,6,FALSE) -> #N/A | AD40: =VLOOKUP($C40,[1]量産!$C$4:$N$15550,7,FALSE) -> #N/A | AE40: =VLOOKUP($C40,[1]量産!$C$4:$N$15550,8,FALSE) -> #N/A | AF40: =VLOOKUP($C40,[1]量産!$C$4:$N$15550,9,FALSE) -> #N/A | AG40: =VLOOKUP($C40,[1]量産!$C$4:$N$15550,10,FALSE) -> #N/A | AH40: =VLOOKUP($C40,[1]量産!$C$4:$N$15550,11,FALSE) -> #N/A | AI40: =VLOOKUP($C40,[1]量産!$C$4:$N$15550,12,FALSE) -> #N/A | AL40: =C40 -> 7552472980 | AM40: =B40 | AN40: =E40 -> I3K6135 | AQ40: =VLOOKUP(AP40,AL40:AM894,2,FALSE) -> 0 | AR40: =VLOOKUP(AP40,AL40:AN894,3,FALSE) -> 0 | BK40: =VLOOKUP(C:C,[2]Sheet2!$A:$A,1,FALSE) -> 7552472980
...

Sheet 設変
V1: 藤沢工場 生産管理課
B2: 小型FRAME Weekly MTG | V2: 承認 | W2: 審査 | X2: 作成 | AA2: ○ | AB2: ：参加
V3: 井上 | X3: 石澤 | AA3: ― | AB3: ：不参加
C5: 【出席者】
D6: 技術課 | K6: 品管課 | M6: 組一課 | P6: 自動車営業部 | S6: 設計部 | U6: 調達 | V6: プレス | W6: 生管課
D7: 松本課長 | E7: 笹主任 | F7: 櫻井担当 | G7: 長田担当 | H7: 高橋担当 | I7: イー担当 | J7: 宮澤担当 | K7: 大木担当 | L7: 川口担当 | M7: 前田次長 | N7: 川上課長 | O7: 綿引担当 | P7: 吉永課長 | Q7: 斉木主任 | R7: 岡担当 | S7: 郡上主任 | T7: 瀧澤担当 | U7: 木村担当 | V7: 福島主任 | W7: 長友主任 | X7: 中村担当 | Y7: 三浦担当 | Z7: 伊藤担当 | AA7: 寺田
C8: 設変 | D8: ― | E8: ○ | F8: ○ | G8: ○ | H8: ○ | I8: ○ | J8: ○ | K8: ○ | L8: ― | M8: ― | N8: ― | O8: ― | P8: ― | Q8: ― | R8: ○ | S8: ○ | T8: ― | U8: ― | V8: ○ | W8: ○ | X8: ― | Y8: ○ | Z8: ○ | AA8: ○
C9: 量産 | D9: ― | E9: ○ | F9: ○ | G9: ― | H9: ○ | I9: ○ | J9: ○ | K9: ○ | L9: ― | M9: ― | N9: ○ | O9: ○ | P9: ― | Q9: ― | R9: ― | S9: ― | T9: ― | U9: ― | V9: ○ | W9: ― | X9: ― | Y9: ○ | Z9: ○ | AA9: ○
C12: 先週受領の設変
B22: SPACER単品出図
B23: フルエア 850幅
B35: 酸洗材化

Sheet 25-38-D
A1: No. | B1: ライン | C1: 納入品番1 | D1: 納入品名称 | E1: 基本車型 | F1: 車型名称 | G1: イベント | H1: 荷姿 | I1: 刻印 | J1: 初品区分 | K1: 初品納入日 | L1: 初日台数 | M1: 0910 | N1: 0911 | O1: 0912 | P1: 0913 | Q1: 0915 | R1: 0916 | S1: 0917 | T1: 0918 | U1: 0919 | V1: 総計
A2: 3 | B2: A | C2: 7552701721 | D2: FRAME ASM | E2: VK05 | F2: VK05 NMR | G2: I4K6545VK05 A,B,C-GR 1生向け設変出図 | H2: 1 | J2: 初 | K2: 45911 | L2: 2 | N2: 2 | V2: 2
A3: 4 | B3: A | C3: 7552701731 | D3: FRAME ASM | E3: VK05 | F3: VK05 NMR | G3: I4K6545VK05 A,B,C-GR 1生向け設変出図 | H3: 1 | J3: 初 | K3: 45912 | L3: 1 | N3: 1 | V3: 1
A4: 8 | B4: C | C4: 7552770110 | D4: FRAME ASM | E4: VK05 | F4: VK05 NPR | G4: VK05 A/B-GR K研向け新規出図 | H4: 1 | I4: HME | J4: 初 | K4: 45914 | L4: 1 | N4: 1 | V4: 1
A5: 9 | B5: C | C5: 7552942680 | D5: FRAME ASM | E5: VK05 | F5: VK05 NPR | G5: VK05 A/B-GR K研向け新規出図 | H5: 1 | I5: HFA | J5: 初 | K5: 45915 | L5: 1 | N5: 1 | V5: 1
A6: 10 | B6: C | C6: 7552942690 | D6: FRAME ASM | E6: VK05 | F6: VK05 NPR | G6: VK05 A/B-GR K研向け新規出図 | H6: 1 | I6: HFB | J6: 初 | K6: 45916 | L6: 3 | N6: 3 | V6: 3
A7: 11 | B7: C | C7: 7552942750 | D7: FRAME ASM | E7: VK05 | F7: VK05 NPR | G7: VK05 A/B-GR K研向け新規出図 | H7: 1 | I7: HFC | J7: 初 | K7: 45917 | L7: 1 | N7: 1 | V7: 1
A8: 12 | B8: C | C8: 7552942950 | D8: FRAME ASM | E8: VK05 | F8: VK05 NPR | G8: VK05 A/B-GR K研向け新規出図 | H8: 1 | I8: HKG | J8: 初 | K8: 45918 | L8: 1 | N8: 1 | V8: 1
A9: 7 | B9: C | C9: 7552418211 | D9: FRAME ASM | E9: VK00 | F9: VK00 NP* | G9: VK00 3X 850幅 B1-GR FRAME ASM 設変出図(内容：FRAME ASM内容品最新化,S/M ASM LH 溶接NUT及びSTIFF SUB SPG BRKT追加,RIVET削除,REINF LH 溶接NUT追加) | H9: 1 | I9: HMB | J9: 初 | K9: 45913 | L9: 1 | N9: 1 | V9: 1
A10: 16 | B10: C | C10: 7552418121 | D10: FRAME ASM | E10: VK00 | F10: VK00 NP* | G10: VK00 3X 850幅 B1-GR FRAME ASM 設変出図(内容：FRAME ASM内容品最新化,S/M ASM LH 溶接NUT及びSTIFF SUB SPG BRKT追加,RIVET削除,REINF LH 溶接NUT追加) | H10: 3 | I10: HKH | J10: 初 | K10: 45919 | L10: 6 | N10: 6 | V10: 6
A11: 5 | B11: A | C11: 8978845054 | D11: FRAME ASM | E11: VK04 | F11: VK04 NMS | G11: VK04 A2-GR 1生向け設変出図 | H11: 1 | I11: PHA | J11: 初 | K11: 45913 | L11: 1 | P11: 1 | V11: 1
A12: 14 | B12: C | C12: 8977917770 | D12: FRAME ASM | E12: VL32 | F12: VL32 NPR | G12: VL32 D2-GR 850幅 FRAME ASM SOP 新規出図 | H12: 1 | I12: UFL | J12: 初 | K12: 45918 | L12: 1 | T12: 1 | U12: 1 | V12: 2
A13: 6 | B13: A | C13: 8983922641 | D13: FRAME ASM | E13: VL01 | F13: VL01 NMR | G13: 久しぶり | H13: 1 | I13: KDL | J13: 久 | K13: 45913 | L13: 2 | P13: 2 | Q13: 1 | R13: 1 | S13: 2 | V13: 6
B14: A | C14: 7551885412 | D14: FRAME ASM | E14: VK00 | F14: VK00 NPR | G14: 久しぶり | H14: 1 | I14: 1RS2 | J14: 久 | K14: 45913 | L14: 1 | P14: 1 | V14: 1
A15: 13 | B15: C | C15: 8975246721 | D15: FRAME ASM | E15: VL01 | F15: VL01 NPR | G15: 久しぶり | H15: 1 | I15: 1UF4 | J15: 久 | K15: 45918 | L15: 3 | T15: 3 | U15: 3 | V15: 6
A16: 2 | B16: A | C16: 7552078350 | D16: FRAME ASM | E16: VL35 | F16: VL35 NKS | G16: 久しぶり | H16: 1 | I16: NJH | J16: 久 | K16: 45918 | L16: 1 | T16: 1 | V16: 1
A17: 15 | B17: C | C17: 8983991350 | D17: FRAME ASM | E17: NPR | F17: NPR | G17: 久しぶり | H17: 1 | I17: WMG | J17: 久 | K17: 45919 | L17: 2 | U17: 2 | V17: 2
A18: 17 | B18: C | C18: 7552434120 | D18: FRAME ASM | E18: VL37 | F18: VL37 NPR | G18: 久しぶり | H18: 3 | I18: YKD | J18: 久 | K18: 45912 | L18: 12 | O18: 12 | Q18: 18 | R18: 18 | S18: 24 | T18: 12 | V18: 84
A19: 18 | B19: C | C19: 7552434130 | D19: FRAME ASM | E19: VL37 | F19: VL37 NPR | G19: 久しぶり | H19: 3 | I19: YSF | J19: 久 | K19: 912 | L19: 6 | O19: 6 | Q19: 6 | R19: 6 | S19: 6 | T19: 12 | V19: 36
A20: 19 | B20: C | C20: 7552434150 | D20: FRAME ASM | E20: VL37 | F20: VL37 NPR | G20: 久しぶり | H20: 3 | I20: YSG | J20: 久 | K20: 912 | L20: 6 | O20: 6 | Q20: 6 | V20: 12
A21: 22 | B21: C | C21: 7552434180 | D21: FRAME ASM | E21: VL37 | F21: VL37 NQR | G21: 久しぶり | H21: 3 | I21: YSD | J21: 久 | K21: 912 | L21: 18 | O21: 18 | Q21: 6 | R21: 6 | S21: 6 | T21: 12 | V21: 48
A22: 24 | B22: C | C22: 7552434200 | D22: FRAME ASM | E22: VL37 | F22: VL37 NQR | G22: 久しぶり | H22: 3 | I22: YSE | J22: 久 | K22: 912 | L22: 6 | O22: 6 | T22: 6 | V22: 12
A23: 20 | B23: C | C23: 7552434160 | D23: FRAME ASM | E23: VL37 | F23: VL37 NQR | G23: 久しぶり | H23: 3 | I23: YE7 | J23: 久 | K23: 915 | L23: 6 | Q23: 6 | V23: 6
A24: 21 | B24: C | C24: 7552434170 | D24: FRAME ASM | E24: VL37 | F24: VL37 NQR | G24: 久しぶり | H24: 3 | I24: YKF | J24: 久 | K24: 916 | L24: 6 | R24: 6 | S24: 6 | V24: 12
A25: 23 | B25: C | C25: 7552434190 | D25: FRAME ASM | E25: VL37 | F25: VL37 NQR | G25: 久しぶり | H25: 3 | I25: YKG | J25: 久 | K25: 916 | L25: 6 | R25: 6 | V25: 6

Sheet 25-37-D
A1: No. | B1: ライン | C1: 納入品番1 | D1: 納入品名称 | E1: 基本車型 | F1: 車型名称 | G1: イベント | H1: 荷姿 | I1: 刻印 | J1: 初品区分 | K1: 初品納入日 | L1: 初日台数 | M1: 0901 | N1: 0903 | O1: 0904 | P1: 0905 | Q1: 0906 | R1: 0908 | S1: 0909 | T1: 0910 | U1: 0911 | V1: 0912 | W1: 0913 | X1: 総計
A2: 1 | B2: A | C2: 7552127032 | D2: FRAME ASM | E2: VK00 | F2: VK00 NPR | G2: I4K4885VK00 B2-GR 750幅 | H2: 1 | J2: 初 | K2: 45906 | L2: 2 | Q2: 2 | X2: 2
A3: 2 | B3: A | C3: 7552078330 | D3: FRAME ASM | E3: VL35 | F3: VL35 NKS | G3: I3JCB85VL35 700幅FRAME ASM | H3: 1 | I3: NJE | J3: 初 | K3: 45909 | L3: 2 | S3: 2 | T3: 1 | V3: 1 | X3: 4
A4: 3 | B4: A | C4: 8972760034 | D4: FRAME ASM | E4: VK04 | F4: VK04 NKS | G4: VK04 A1-GR 1生向け設変出図 | H4: 1 | I4: MC3 | J4: 初 | K4: 45909 | L4: 2 | S4: 2 | T4: 2 | X4: 4
A5: 4 | B5: A | C5: 8977943094 | D5: FRAME ASM | E5: VK04 | F5: VK04 NKR | G5: 新規作成 FRAME ASM VK04 NKR 8977943115_44_3094 | H5: 1 | J5: 初 | K5: 45909 | L5: 1 | S5: 1 | X5: 1
A6: 5 | B6: A | C6: 8977943473 | D6: FRAME ASM | E6: VK04 | F6: VK04 NMS | G6: VK04 A1-GR 1生向け設変出図 | H6: 1 | J6: 初 | K6: 45909 | L6: 1 | S6: 1 | X6: 1
A7: 6 | B7: A | C7: 8978767523 | D7: FRAME ASM | E7: VK04 | F7: VK04 NMS | G7: VK04 A1-GR 1生向け設変出図 | H7: 1 | J7: 初 | K7: 45909 | L7: 1 | S7: 1 | X7: 1
A8: 7 | B8: A | C8: 8972760044 | D8: FRAME ASM | E8: VK04 | F8: VK04 NKS | G8: VK04 A1-GR 1生向け設変出図 | H8: 1 | I8: MC4 | J8: 初 | K8: 45910 | L8: 7 | T8: 7 | U8: 7 | V8: 7 | X8: 21
A9: 8 | B9: A | C9: 8978767342 | D9: FRAME ASM | E9: VK00 | F9: VK00 NKR | G9: VK00 1X RIGID 一生向けFRAME ASM 設変出図I4JKG68 | H9: 1 | J9: 初 | K9: 45910 | L9: 1 | T9: 1 | X9: 1
A10: 9 | B10: A | C10: 8978767254 | D10: FRAME ASM | E10: VK04 | F10: VK04 NKR | G10: VK04 A1-GR 1生向け設変出図 | H10: 1 | J10: 初 | K10: 45911 | L10: 3 | U10: 3 | X10: 3
A11: 10 | B11: A | C11: 8978767385 | D11: FRAME ASM | E11: VK04 | F11: VK04 NKR | G11: VK04 A1-GR 1生向け設変出図 | H11: 1 | J11: 初 | K11: 45912 | L11: 2 | V11: 2 | X11: 2
A12: 11 | B12: A | C12: 7552127093 | D12: FRAME ASM | E12: VK00 | F12: VK00 NPR | G12: 久しぶり | H12: 1 | I12: RH1 | J12: 久 | K12: 45906 | L12: 6 | Q12: 6 | R12: 3 | S12: 7 | T12: 7 | U12: 6 | V12: 6 | X12: 35
A13: 12 | B13: A | C13: 8983922641 | D13: FRAME ASM | E13: VL01 | F13: VL01 NMR | G13: 久しぶり | H13: 1 | I13: KDL | J13: 久 | K13: 906 | L13: 1 | Q13: 1 | T13: 1 | X13: 2
A14: 13 | B14: C | C14: 8975587571 | D14: FRAME ASM | E14: VL20 | F14: VL20 NPR | G14: 久しぶり | H14: 1 | I14: 1W1C | J14: 久 | K14: 906 | L14: 2 | Q14: 2 | S14: 1 | T14: 1 | U14: 1 | V14: 1 | X14: 6
A15: 14 | B15: C | C15: 7552434190 | D15: FRAME ASM | E15: VL37 | F15: VL37 NQR | G15: 久しぶり | H15: 3 | I15: YKG | J15: 久 | K15: 908 | L15: 6 | R15: 6 | X15: 6
A16: 15 | B16: A | C16: 8983922630 | D16: FRAME ASM | E16: VL01 | F16: VL01 NMR | G16: 久しぶり | H16: 1 | I16: KDU | J16: 久 | K16: 909 | L16: 1 | S16: 1 | T16: 1 | X16: 2
A17: 16 | B17: C | C17: 8983152572 | D17: FRAME ASM | E17: VN97 | F17: VN97 NPS | G17: 久しぶり | H17: 3 | I17: UK1 | J17: 久 | K17: 909 | L17: 6 | S17: 6 | X17: 6
A18: 17 | B18: C | C18: 8978844520 | D18: FRAME ASM | E18: VL01 | F18: VL01 NPS | G18: 久しぶり | H18: 1 | I18: UFJ | J18: 久 | K18: 910 | L18: 1 | T18: 1 | U18: 1 | X18: 2
A19: 18 | B19: A | C19: 7552078870 | D19: FRAME ASM | E19: VL35 | F19: VL35 NPS | G19: 久しぶり | H19: 1 | I19: TEU | J19: 久 | K19: 911 | L19: 1 | U19: 1 | X19: 1
A20: 19 | B20: C | C20: 8983906740 | D20: FRAME ASM | E20: VL01 | F20: VL01 NPR | G20: 久しぶり | H20: 1 | I20: WGF | J20: 久 | K20: 911 | L20: 4 | U20: 4 | V20: 5 | X20: 9
A21: 20 | B21: A | C21: 7551885402 | D21: FRAME ASM | E21: VK00 | F21: VK00 NPR | G21: 久しぶり | H21: 1 | I21: 1RS1 | J21: 久 | K21: 912 | L21: 1 | V21: 1 | X21: 1
A22: 21 | B22: A | C22: 8974948780 | D22: FRAME ASM | E22: VL01 | F22: VL01 NMR | G22: 久しぶり | H22: 1 | I22: LLN | J22: 久 | K22: 912 | L22: 1 | V22: 1 | X22: 1
A23: 27 | B23: C | C23: 7552434200 | D23: FRAME ASM | E23: VL37 | F23: VL37 NQR | G23: 久しぶり | H23: 3 | I23: YSE | J23: 久 | K23: 911 | L23: 12 | U23: 12 | X23: 12
A24: 23 | B24: C | C24: 7552434160 | D24: FRAME ASM | E24: VL37 | F24: VL37 NQR | G24: 久しぶり | H24: 3 | I24: YE7 | J24: 久 | K24: 910 | L24: 6 | T24: 6 | U24: 6 | X24: 12
A25: 25 | B25: C | C25: 7552434180 | D25: FRAME ASM | E25: VL37 | F25: VL37 NQR | G25: 久しぶり | H25: 3 | I25: YSD | J25: 久 | K25: 908 | L25: 6 | R25: 6 | S25: 6 | T25: 6 | U25: 6 | X25: 24
A26: 20 | B26: C | C26: 7552434120 | D26: FRAME ASM | E26: VL37 | F26: VL37 NPR | G26: 久しぶり | H26: 3 | I26: YKD | J26: 久 | K26: 905 | L26: 18 | P26: 18 | R26: 18 | S26: 12 | T26: 12 | U26: 18 | X26: 78
A27: 21 | B27: C | C27: 7552434130 | D27: FRAME ASM | E27: VL37 | F27: VL37 NPR | G27: 久しぶり | H27: 3 | I27: YSF | J27: 久 | K27: 905 | L27: 12 | P27: 12 | R27: 12 | S27: 6 | T27: 6 | X27: 36
A28: 22 | B28: C | C28: 7552434150 | D28: FRAME ASM | E28: VL37 | F28: VL37 NPR | G28: 久しぶり | H28: 3 | I28: YSG | J28: 久 | K28: 905 | L28: 6 | P28: 6 | R28: 6 | T28: 6 | X28: 18
A29: 24 | B29: C | C29: 7552434170 | D29: FRAME ASM | E29: VL37 | F29: VL37 NQR | G29: 久しぶり | H29: 3 | I29: YKF | J29: 久 | K29: 905 | L29: 6 | P29: 6 | R29: 6 | S29: 12 | T29: 6 | X29: 30

Sheet 25-36-D
A1: No. | B1: ライン | C1: 納入品番1 | D1: 納入品名称 | E1: 基本車型 | F1: 車型名称 | G1: イベント | H1: 荷姿 | I1: 刻印 | J1: 初品区分 | K1: 初品納入日 | L1: 初日台数 | M1: 0826 | N1: 0828 | O1: 0829 | P1: 0830 | Q1: 0901 | R1: 0902 | S1: 0903 | T1: 0904 | U1: 0905 | V1: 0906 | W1: 総計
A2: 1 | B2: 115 | C2: 7552702910 | D2: FRAME ASM | E2: VK05 | F2: VK05 | G2: I4K5796VK04 A2-GR 1生向け設変出図 | H2: 1 | I2: DBT | J2: 初 | K2: 45897 | L2: 7 | N2: 7 | W2: 7
A3: 2 | B3: 115 | C3: 7552702950 | D3: FRAME ASM | E3: VK05 | F3: VK05 | G3: VK04 A2-GR 1生向け設変出図 | H3: 1 | I3: FBC | J3: 初 | K3: 45897 | L3: 2 | N3: 2 | W3: 2
A4: 3 | B4: 115 | C4: 7552702980 | D4: FRAME ASM | E4: NMR | F4: VK00 NMR | G4: I4K6308VK02 A-GR 1生向け設変出図 | H4: 1 | I4: DBV | J4: 初 | K4: 45897 | L4: 2 | N4: 2 | W4: 2
A5: 4 | B5: 115 | C5: 7552703020 | D5: FRAME ASM | E5: NMR | F5: NMR | G5: VK04 A2-GR SOP向け設変出図 | H5: 1 | I5: FBD | J5: 初 | K5: 45897 | L5: 1 | N5: 1 | W5: 1
A6: 5 | B6: 115 | C6: 7552715040 | D6: FRAME ASM | E6: NMR | F6: NMR | G6: VK04 A2-GR SOP向け設変出図 | H6: 1 | I6: FBE | J6: 初 | K6: 45897 | L6: 1 | N6: 1 | W6: 1
A7: 6 | B7: 115 | C7: 7552715090 | D7: FRAME ASM | E7: NMR | F7: NMR | G7: VK04 A2-GR SOP向け設変出図 | H7: 1 | I7: DBZ | J7: 初 | K7: 45897 | L7: 2 | N7: 2 | W7: 2
A8: 7 | B8: 115 | C8: 7552715100 | D8: FRAME ASM | E8: NMR | F8: NMR | G8: VK04 A2-GR SOP向け設変出図 | H8: 1 | I8: DCA | J8: 初 | K8: 45897 | L8: 2 | N8: 2 | W8: 2
A9: 8 | B9: C | C9: 7552770121 | D9: FRAME ASM | E9: VK05 | F9: VK05 NP* | G9: VK05 C-GR 1生向け 設変出図 | H9: 1 | I9: UA2 | J9: 初 | K9: 45898 | L9: 1 | O9: 1 | W9: 1
A10: 9 | B10: A | C10: 7551946451 | D10: FRAME ASM | E10: VK00 | F10: VK00 NMR | G10: I3K4234VK00 B1-GR | H10: 1 | J10: 初 | K10: 45899 | L10: 1 | P10: 1 | W10: 1
A11: 10 | B11: A | C11: 7552127212 | D11: FRAME ASM | E11: VK00 | F11: VK00 NPR | G11: VK00 B2-GR 750幅 FRAME ASM 設変出図 | H11: 1 | J11: 初 | K11: 45899 | L11: 1 | P11: 1 | R11: 2 | S11: 1 | W11: 4
A12: 11 | B12: A | C12: 7552378410 | D12: FRAME ASM | E12: VK00 | F12: VK00 NMR | G12: I3K4234VK00 B1-GR 一生向け FRAME ASM 新規出図 | H12: 1 | J12: 初 | K12: 45899 | L12: 1 | P12: 1 | W12: 1
A13: 12 | B13: A | C13: 8972760044 | D13: FRAME ASM | E13: VK04 | F13: VK04 NKS | G13: VK04 A1-GR 1生向け設変出図 | H13: 1 | J13: 初 | K13: 45899 | L13: 3 | P13: 3 | S13: 3 | T13: 2 | U13: 2 | W13: 10
A14: 13 | C14: 7552078330 | D14: FRAME ASM | E14: VL35 | F14: VL35 NKS | G14: VL35 700幅FRAME ASM 新規出図(初回イベント:’23/7月 一生) | H14: 1 | J14: 初 | K14: 45902 | L14: 1 | R14: 1 | W14: 1
A15: 14 | B15: A | C15: 8972760034 | D15: FRAME ASM | E15: VK04 | F15: VK04 NKS | G15: VK04 A1-GR 1生向け設変出図 | H15: 1 | J15: 初 | K15: 45902 | L15: 1 | R15: 1 | W15: 1
A16: 15 | B16: A | C16: 7552378260 | D16: FRAME ASM | E16: VK00 | F16: VK00 NMR | G16: I3K4234VK00 B1-GR | H16: 1 | J16: 初 | K16: 45905 | L16: 1 | U16: 1 | W16: 1
A17: 16 | B17: A | C17: 7551885552 | D17: FRAME ASM | E17: VK00 | F17: VK00 NPR | G17: 久しぶり | H17: 1 | I17: SFY | J17: 久 | K17: 45899 | L17: 1 | P17: 1 | W17: 1
A18: 17 | B18: A | C18: 7552127093 | D18: FRAME ASM | E18: VK00 | F18: VK00 NPR | G18: 久しぶり | H18: 1 | I18: RH1 | J18: 久 | K18: 45899 | L18: 11 | P18: 11 | Q18: 1 | R18: 8 | S18: 9 | U18: 8 | W18: 37
A19: 18 | B19: C | C19: 8975587571 | D19: FRAME ASM | E19: VL20 | F19: VL20 NPR | G19: 久しぶり | H19: 1 | I19: 1W1C | J19: 久 | K19: 45899 | L19: 1 | P19: 1 | Q19: 1 | R19: 2 | S19: 1 | T19: 1 | U19: 1 | W19: 7
A20: 19 | B20: C | C20: 8976840280 | D20: FRAME ASM | E20: VL24 | F20: VL24 NPR | G20: 久しぶり | H20: 1 | I20: WFD | J20: 久 | K20: 45899 | L20: 1 | P20: 1 | W20: 1
A21: 20 | B21: C | C21: 8982261483 | D21: FRAME ASM | E21: VL08 | F21: VL08 NPR | G21: 久しぶり | H21: 1 | I21: 2WNX | J21: 久 | K21: 45899 | L21: 1 | P21: 1 | W21: 1
A22: 21 | B22: C | C22: 8984857931 | D22: FRAME ASM | E22: VL01 | F22: VL01 NPR | G22: 久しぶり | H22: 1 | I22: W1U | J22: 久 | K22: 45899 | L22: 1 | P22: 1 | T22: 1 | U22: 1 | W22: 3
A23: 22 | B23: A | C23: 7551909340 | D23: FRAME ASM | E23: VK00 | F23: VK00 NKR | G23: 久しぶり | H23: 1 | I23: PW6 | J23: 久 | K23: 45901 | L23: 1 | Q23: 1 | W23: 1
A24: 23 | B24: A | C24: 8976762403 | D24: FRAME ASM | E24: VL27 | F24: VL27 NNR | G24: 久しぶり | H24: 1 | I24: 1RR6 | J24: 久 | K24: 45901 | L24: 1 | Q24: 1 | W24: 1
A25: 24 | B25: C | C25: 7552282602 | D25: FRAME ASM | E25: VK00 | F25: VK00 N** | G25: 久しぶり | H25: 1 | I25: HMA | J25: 久 | K25: 45902 | L25: 1 | R25: 1 | W25: 1
A26: 25 | B26: C | C26: 8982261553 | D26: FRAME ASM | E26: VN80 | F26: VN80 NPR | G26: 久しぶり | H26: 1 | I26: WV5 | J26: 久 | K26: 45902 | L26: 1 | R26: 1 | W26: 1
A27: 26 | B27: C | C27: 8983707530 | D27: FRAME ASM | E27: VL08 | F27: VL08 NPR | G27: 久しぶり | H27: 1 | I27: WTC | J27: 久 | K27: 45903 | L27: 1 | S27: 1 | W27: 1
A28: 27 | B28: C | C28: 8983906740 | D28: FRAME ASM | E28: VL01 | F28: VL01 NPR | G28: 久しぶり | H28: 1 | I28: WGF | J28: 久 | K28: 45903 | L28: 1 | S28: 1 | T28: 3 | U28: 3 | W28: 7
A29: 28 | B29: C | C29: 8983152572 | D29: FRAME ASM | E29: VN97 | F29: VN97 NPS | G29: 久しぶり | H29: 3 | I29: UK1 | J29: 久 | K29: 45903 | L29: 6 | S29: 6 | W29: 6
A30: 29 | B30: C | C30: 7552282562 | D30: FRAME ASM | E30: VK00 | F30: VK00 N** | G30: 久しぶり | H30: 1 | I30: HM9 | J30: 久 | K30: 45904 | L30: 1 | T30: 1 | W30: 1
A31: 30 | B31: C | C31: 8977917730 | D31: FRAME ASM | E31: VL20 | F31: VL20 NQR | G31: 久しぶり | H31: 1 | I31: WSU | J31: 久 | K31: 45904 | L31: 1 | T31: 1 | W31: 1
A32: 31 | B32: C | C32: 8983707131 | D32: FRAME ASM | E32: VL08 N | F32: VL08 NPR | G32: 久しぶり | H32: 1 | I32: WBA | J32: 久 | K32: 45904 | L32: 1 | T32: 1 | W32: 1
